Workbook

Sheet Week1
A1: Gazebo HR — Week 1
A2: Period: D 20/04/2026 to D 26/04/2026
A4: Week 1 — Employee paid hours
A5: One row per employee for this pay week (from weekly export).
A6: Name | B6: Category | C6: Pay ID (Sage) | D6: Basic hours | E6: Mon–Fri overtime | F6: Sat/Sun overtime | G6: Annual holiday | H6: Total paid hours
A7: K CARSANE | B7: CLNR | C7: 692 | D7: 41.25 | E7: 3.25 | F7: 0 | G7: 0 | H7: 44.5
A8: D GIVA | B8: CLNR | C8: 718 | D8: 40 | E8: 0.5 | F8: 0 | G8: 0 | H8: 40.5
A9: D KUMAR NARANBHAI RATHOD | B9: CLNR | C9: 629 | D9: 40 | E9: 0 | F9: 0 | G9: 0 | H9: 40
A10: D NATU | B10: CLNR | C10: 750 | D10: 41.25 | E10: 0.25 | F10: 0 | G10: 0 | H10: 41.5
A11: S NATU | B11: CLNR | C11: 579 | D11: 0 | E11: 5 | F11: 10.75 | G11: 0 | H11: 15.75
A12: T TIRKEY | B12: CLNR | C12: 506 | D12: 39.5 | E12: 0 | F12: 0 | G12: 0 | H12: 39.5
A13: U VINAYCHANDRA | B13: DPCH | C13: 426 | D13: 41.25 | E13: 26.5 | F13: 0 | G13: 0 | H13: 67.75
A14: S BHIMJI VAGADIYA | B14: OFCE | C14: 749 | D14: 20 | E14: 0 | F14: 0 | G14: 0 | H14: 20
A15: D DEVUSINH BAROT | B15: OFCE | C15: 752 | D15: 41.25 | E15: 3.25 | F15: 0 | G15: 0 | H15: 44.5
A16: B DIKER | B16: OFCE | C16: 747 | D16: 41.25 | E16: 7.75 | F16: 0 | G16: 0 | H16: 49
A17: U GOHEL | B17: OFCE | C17: 691 | D17: 0 | E17: 0 | F17: 0 | G17: 0 | H17: 0
A18: P LEITE | B18: OFCE | C18: 504 | D18: 41.25 | E18: 4.5 | F18: 2.75 | G18: 0 | H18: 48.5
... A203: A DABGAR RESPONSE | B203: A-RS PROD FRYING | C203: 0 | D203: 0 | E203: 0 | F203: 0 | G203: 0 | H203: 0
A205: Adjustments (0)
A206: Manual hour corrections recorded in the legacy weekly file.
B207: Name | C207: Type | D207: Value
A209: Category totals
A210: Sum of hours by work category for this week (SUMIFS from employee rows above).
B211: Category | D211: Basic hours | E211: Mon–Fri overtime | F211: Sat/Sun overtime | G211: Annual holiday | H211: Total paid hours
B212: CLNR | D212: =SUMIFS($D$7:$D$203,$B$7:$B$203,$B212) | E212: =SUMIFS($E$7:$E$203,$B$7:$B$203,$B212) | F212: =SUMIFS($F$7:$F$203,$B$7:$B$203,$B212) | G212: =SUMIFS($G$7:$G$203,$B$7:$B$203,$B212) | H212: =SUMIFS($H$7:$H$203,$B$7:$B$203,$B212)
B213: DPCH | D213: =SUMIFS($D$7:$D$203,$B$7:$B$203,$B213) | E213: =SUMIFS($E$7:$E$203,$B$7:$B$203,$B213) | F213: =SUMIFS($F$7:$F$203,$B$7:$B$203,$B213) | G213: =SUMIFS($G$7:$G$203,$B$7:$B$203,$B213) | H213: =SUMIFS($H$7:$H$203,$B$7:$B$203,$B213)
B214: OFCE | D214: =SUMIFS($D$7:$D$203,$B$7:$B$203,$B214) | E214: =SUMIFS($E$7:$E$203,$B$7:$B$203,$B214) | F214: =SUMIFS($F$7:$F$203,$B$7:$B$203,$B214) | G214: =SUMIFS($G$7:$G$203,$B$7:$B$203,$B214) | H214: =SUMIFS($H$7:$H$203,$B$7:$B$203,$B214)
B215: PKNG HIGH_RISK | D215: =SUMIFS($D$7:$D$203,$B$7:$B$203,$B215) | E215: =SUMIFS($E$7:$E$203,$B$7:$B$203,$B215) | F215: =SUMIFS($F$7:$F$203,$B$7:$B$203,$B215) | G215: =SUMIFS($G$7:$G$203,$B$7:$B$203,$B215) | H215: =SUMIFS($H$7:$H$203,$B$7:$B$203,$B215)
B216: PKNG SLEEVING | D216: =SUMIFS($D$7:$D$203,$B$7:$B$203,$B216) | E216: =SUMIFS($E$7:$E$203,$B$7:$B$203,$B216) | F216: =SUMIFS($F$7:$F$203,$B$7:$B$203,$B216) | G216: =SUMIFS($G$7:$G$203,$B$7:$B$203,$B216) | H216: =SUMIFS($H$7:$H$203,$B$7:$B$203,$B216)
B217: PROD BELT | D217: =SUMIFS($D$7:$D$203,$B$7:$B$203,$B217) | E217: =SUMIFS($E$7:$E$203,$B$7:$B$203,$B217) | F217: =SUMIFS($F$7:$F$203,$B$7:$B$203,$B217) | G217: =SUMIFS($G$7:$G$203,$B$7:$B$203,$B217) | H217: =SUMIFS($H$7:$H$203,$B$7:$B$203,$B217)
B218: PROD FORMING | D218: =SUMIFS($D$7:$D$203,$B$7:$B$203,$B218) | E218: =SUMIFS($E$7:$E$203,$B$7:$B$203,$B218) | F218: =SUMIFS($F$7:$F$203,$B$7:$B$203,$B218) | G218: =SUMIFS($G$7:$G$203,$B$7:$B$203,$B218) | H218: =SUMIFS($H$7:$H$203,$B$7:$B$203,$B218)
B219: PROD FRYING | D219: =SUMIFS($D$7:$D$203,$B$7:$B$203,$B219) | E219: =SUMIFS($E$7:$E$203,$B$7:$B$203,$B219) | F219: =SUMIFS($F$7:$F$203,$B$7:$B$203,$B219) | G219: =SUMIFS($G$7:$G$203,$B$7:$B$203,$B219) | H219: =SUMIFS($H$7:$H$203,$B$7:$B$203,$B219)
B220: PROD PREPARATION | D220: =SUMIFS($D$7:$D$203,$B$7:$B$203,$B220) | E220: =SUMIFS($E$7:$E$203,$B$7:$B$203,$B220) | F220: =SUMIFS($F$7:$F$203,$B$7:$B$203,$B220) | G220: =SUMIFS($G$7:$G$203,$B$7:$B$203,$B220) | H220: =SUMIFS($H$7:$H$203,$B$7:$B$203,$B220)
B221: PROD TABLE | D221: =SUMIFS($D$7:$D$203,$B$7:$B$203,$B221) | E221: =SUMIFS($E$7:$E$203,$B$7:$B$203,$B221) | F221: =SUMIFS($F$7:$F$203,$B$7:$B$203,$B221) | G221: =SUMIFS($G$7:$G$203,$B$7:$B$203,$B221) | H221: =SUMIFS($H$7:$H$203,$B$7:$B$203,$B221)
B222: TECH TECHNICAL | D222: =SUMIFS($D$7:$D$203,$B$7:$B$203,$B222) | E222: =SUMIFS($E$7:$E$203,$B$7:$B$203,$B222) | F222: =SUMIFS($F$7:$F$203,$B$7:$B$203,$B222) | G222: =SUMIFS($G$7:$G$203,$B$7:$B$203,$B222) | H222: =SUMIFS($H$7:$H$203,$B$7:$B$203,$B222)
B223: WRHS | D223: =SUMIFS($D$7:$D$203,$B$7:$B$203,$B223) | E223: =SUMIFS($E$7:$E$203,$B$7:$B$203,$B223) | F223: =SUMIFS($F$7:$F$203,$B$7:$B$203,$B223) | G223: =SUMIFS($G$7:$G$203,$B$7:$B$203,$B223) | H223: =SUMIFS($H$7:$H$203,$B$7:$B$203,$B223)
... B236: A-RS PROD FRYING | D236: =SUMIFS($D$7:$D$203,$B$7:$B$203,$B236) | E236: =SUMIFS($E$7:$E$203,$B$7:$B$203,$B236) | F236: =SUMIFS($F$7:$F$203,$B$7:$B$203,$B236) | G236: =SUMIFS($G$7:$G$203,$B$7:$B$203,$B236) | H236: =SUMIFS($H$7:$H$203,$B$7:$B$203,$B236)
A238: Grouped totals (by category prefix)
A239: Categories rolled up to 4-character groups.
B240: Category | D240: Basic hours | E240: Mon–Fri overtime | F240: Sat/Sun overtime | G240: Annual holiday | H240: Total paid hours
...

Sheet Week2
A1: Gazebo HR — Week 2
A2: Period: D 27/04/20269 to D 03/05/20269
A4: Week 2 — Employee paid hours
A5: One row per employee for this pay week (from weekly export).
A6: Name | B6: Category | C6: Pay ID (Sage) | D6: Basic hours | E6: Mon–Fri overtime | F6: Sat/Sun overtime | G6: Annual holiday | H6: Total paid hours
A7: K CARSANE | B7: CLNR | C7: 692 | D7: 41.25 | E7: 2.25 | F7: 0 | G7: 0 | H7: 43.5
A8: D GIVA | B8: CLNR | C8: 718 | D8: 38 | E8: 0 | F8: 0 | G8: 0 | H8: 38
A9: D KUMAR NARANBHAI RATHOD | B9: CLNR | C9: 629 | D9: 39.75 | E9: 0 | F9: 0 | G9: 0 | H9: 39.75
A10: D NATU | B10: CLNR | C10: 750 | D10: 40 | E10: 9.25 | F10: 0 | G10: 0 | H10: 49.25
A11: S NATU | B11: CLNR | C11: 579 | D11: 0 | E11: 9.25 | F11: 8.25 | G11: 0 | H11: 17.5
A12: T TIRKEY | B12: CLNR | C12: 506 | D12: 40 | E12: 9.25 | F12: 0 | G12: 0 | H12: 49.25
A13: U VINAYCHANDRA | B13: DPCH | C13: 426 | D13: 41.25 | E13: 29 | F13: 0 | G13: 0 | H13: 70.25
A14: S BHIMJI VAGADIYA | B14: OFCE | C14: 749 | D14: 20 | E14: 0 | F14: 0 | G14: 0 | H14: 20
A15: D DEVUSINH BAROT | B15: OFCE | C15: 752 | D15: 25.25 | E15: 1.25 | F15: 0 | G15: 16 | H15: 42.5
A16: B DIKER | B16: OFCE | C16: 747 | D16: 41.25 | E16: 12.25 | F16: 0 | G16: 0 | H16: 53.5
A17: U GOHEL | B17: OFCE | C17: 691 | D17: 0 | E17: 0 | F17: 0 | G17: 0 | H17: 0
A18: P LEITE | B18: OFCE | C18: 504 | D18: 40.25 | E18: 4.5 | F18: 0 | G18: 0 | H18: 44.75
... A205: A DABGAR RESPONSE | B205: A-RS PROD FRYING | C205: 0 | D205: 0 | E205: 0 | F205: 0 | G205: 0 | H205: 0
A207: Adjustments (0)
A208: Manual hour corrections recorded in the legacy weekly file.
B209: Name | C209: Type | D209: Value
A211: Category totals
A212: Sum of hours by work category for this week (SUMIFS from employee rows above).
B213: Category | D213: Basic hours | E213: Mon–Fri overtime | F213: Sat/Sun overtime | G213: Annual holiday | H213: Total paid hours
B214: CLNR | D214: =SUMIFS($D$7:$D$205,$B$7:$B$205,$B214) | E214: =SUMIFS($E$7:$E$205,$B$7:$B$205,$B214) | F214: =SUMIFS($F$7:$F$205,$B$7:$B$205,$B214) | G214: =SUMIFS($G$7:$G$205,$B$7:$B$205,$B214) | H214: =SUMIFS($H$7:$H$205,$B$7:$B$205,$B214)
B215: DPCH | D215: =SUMIFS($D$7:$D$205,$B$7:$B$205,$B215) | E215: =SUMIFS($E$7:$E$205,$B$7:$B$205,$B215) | F215: =SUMIFS($F$7:$F$205,$B$7:$B$205,$B215) | G215: =SUMIFS($G$7:$G$205,$B$7:$B$205,$B215) | H215: =SUMIFS($H$7:$H$205,$B$7:$B$205,$B215)
B216: OFCE | D216: =SUMIFS($D$7:$D$205,$B$7:$B$205,$B216) | E216: =SUMIFS($E$7:$E$205,$B$7:$B$205,$B216) | F216: =SUMIFS($F$7:$F$205,$B$7:$B$205,$B216) | G216: =SUMIFS($G$7:$G$205,$B$7:$B$205,$B216) | H216: =SUMIFS($H$7:$H$205,$B$7:$B$205,$B216)
B217: PKNG HIGH_RISK | D217: =SUMIFS($D$7:$D$205,$B$7:$B$205,$B217) | E217: =SUMIFS($E$7:$E$205,$B$7:$B$205,$B217) | F217: =SUMIFS($F$7:$F$205,$B$7:$B$205,$B217) | G217: =SUMIFS($G$7:$G$205,$B$7:$B$205,$B217) | H217: =SUMIFS($H$7:$H$205,$B$7:$B$205,$B217)
B218: PKNG SLEEVING | D218: =SUMIFS($D$7:$D$205,$B$7:$B$205,$B218) | E218: =SUMIFS($E$7:$E$205,$B$7:$B$205,$B218) | F218: =SUMIFS($F$7:$F$205,$B$7:$B$205,$B218) | G218: =SUMIFS($G$7:$G$205,$B$7:$B$205,$B218) | H218: =SUMIFS($H$7:$H$205,$B$7:$B$205,$B218)
B219: PROD BELT | D219: =SUMIFS($D$7:$D$205,$B$7:$B$205,$B219) | E219: =SUMIFS($E$7:$E$205,$B$7:$B$205,$B219) | F219: =SUMIFS($F$7:$F$205,$B$7:$B$205,$B219) | G219: =SUMIFS($G$7:$G$205,$B$7:$B$205,$B219) | H219: =SUMIFS($H$7:$H$205,$B$7:$B$205,$B219)
B220: PROD FORMING | D220: =SUMIFS($D$7:$D$205,$B$7:$B$205,$B220) | E220: =SUMIFS($E$7:$E$205,$B$7:$B$205,$B220) | F220: =SUMIFS($F$7:$F$205,$B$7:$B$205,$B220) | G220: =SUMIFS($G$7:$G$205,$B$7:$B$205,$B220) | H220: =SUMIFS($H$7:$H$205,$B$7:$B$205,$B220)
B221: PROD FRYING | D221: =SUMIFS($D$7:$D$205,$B$7:$B$205,$B221) | E221: =SUMIFS($E$7:$E$205,$B$7:$B$205,$B221) | F221: =SUMIFS($F$7:$F$205,$B$7:$B$205,$B221) | G221: =SUMIFS($G$7:$G$205,$B$7:$B$205,$B221) | H221: =SUMIFS($H$7:$H$205,$B$7:$B$205,$B221)
B222: PROD PREPARATION | D222: =SUMIFS($D$7:$D$205,$B$7:$B$205,$B222) | E222: =SUMIFS($E$7:$E$205,$B$7:$B$205,$B222) | F222: =SUMIFS($F$7:$F$205,$B$7:$B$205,$B222) | G222: =SUMIFS($G$7:$G$205,$B$7:$B$205,$B222) | H222: =SUMIFS($H$7:$H$205,$B$7:$B$205,$B222)
B223: PROD TABLE | D223: =SUMIFS($D$7:$D$205,$B$7:$B$205,$B223) | E223: =SUMIFS($E$7:$E$205,$B$7:$B$205,$B223) | F223: =SUMIFS($F$7:$F$205,$B$7:$B$205,$B223) | G223: =SUMIFS($G$7:$G$205,$B$7:$B$205,$B223) | H223: =SUMIFS($H$7:$H$205,$B$7:$B$205,$B223)
B224: TECH TECHNICAL | D224: =SUMIFS($D$7:$D$205,$B$7:$B$205,$B224) | E224: =SUMIFS($E$7:$E$205,$B$7:$B$205,$B224) | F224: =SUMIFS($F$7:$F$205,$B$7:$B$205,$B224) | G224: =SUMIFS($G$7:$G$205,$B$7:$B$205,$B224) | H224: =SUMIFS($H$7:$H$205,$B$7:$B$205,$B224)
B225: WRHS | D225: =SUMIFS($D$7:$D$205,$B$7:$B$205,$B225) | E225: =SUMIFS($E$7:$E$205,$B$7:$B$205,$B225) | F225: =SUMIFS($F$7:$F$205,$B$7:$B$205,$B225) | G225: =SUMIFS($G$7:$G$205,$B$7:$B$205,$B225) | H225: =SUMIFS($H$7:$H$205,$B$7:$B$205,$B225)
... B239: A-RS PROD FRYING | D239: =SUMIFS($D$7:$D$205,$B$7:$B$205,$B239) | E239: =SUMIFS($E$7:$E$205,$B$7:$B$205,$B239) | F239: =SUMIFS($F$7:$F$205,$B$7:$B$205,$B239) | G239: =SUMIFS($G$7:$G$205,$B$7:$B$205,$B239) | H239: =SUMIFS($H$7:$H$205,$B$7:$B$205,$B239)
A241: Grouped totals (by category prefix)
A242: Categories rolled up to 4-character groups.
B243: Category | D243: Basic hours | E243: Mon–Fri overtime | F243: Sat/Sun overtime | G243: Annual holiday | H243: Total paid hours
...

Sheet Week3
A1: Gazebo HR — Week 3
A2: Period: D 04/05/2026 to D 10/05/2026
A4: Week 3 — Employee paid hours
A5: One row per employee for this pay week (from weekly export).
A6: Name | B6: Category | C6: Pay ID (Sage) | D6: Basic hours | E6: Mon–Fri overtime | F6: Sat/Sun overtime | G6: Annual holiday | H6: Total paid hours
A7: K CARSANE | B7: CLNR | C7: 692 | D7: 33.25 | E7: 18 | F7: 0 | G7: 8 | H7: 59.25
A8: D GIVA | B8: CLNR | C8: 718 | D8: 33.25 | E8: 0.75 | F8: 5.5 | G8: 8 | H8: 47.5
A9: D KUMAR NARANBHAI RATHOD | B9: CLNR | C9: 629 | D9: 33.25 | E9: 7 | F9: 0 | G9: 8 | H9: 48.25
A10: D NATU | B10: CLNR | C10: 750 | D10: 33.25 | E10: 6.25 | F10: 6.75 | G10: 8 | H10: 54.25
A11: S NATU | B11: CLNR | C11: 579 | D11: 0 | E11: 10.25 | F11: 0 | G11: 8 | H11: 18.25
A12: T TIRKEY | B12: CLNR | C12: 506 | D12: 33.25 | E12: 15.25 | F12: 0 | G12: 8 | H12: 56.5
A13: U VINAYCHANDRA | B13: DPCH | C13: 426 | D13: 33.25 | E13: 34 | F13: 0 | G13: 8 | H13: 75.25
A14: S BHIMJI VAGADIYA | B14: OFCE | C14: 749 | D14: 16 | E14: 0 | F14: 0 | G14: 4 | H14: 20
A15: D DEVUSINH BAROT | B15: OFCE | C15: 752 | D15: 0 | E15: 0 | F15: 0 | G15: 16 | H15: 16
A16: B DIKER | B16: OFCE | C16: 747 | D16: 33.25 | E16: 16.25 | F16: 0 | G16: 8 | H16: 57.5
A17: U GOHEL | B17: OFCE | C17: 691 | D17: 0 | E17: 6.25 | F17: 0 | G17: 4 | H17: 10.25
A18: P LEITE | B18: OFCE | C18: 504 | D18: 33 | E18: 2.5 | F18: 0 | G18: 8 | H18: 43.5
... A208: A DABGAR RESPONSE | B208: A-RS PROD FRYING | C208: 0 | D208: 0 | E208: 0 | F208: 0 | G208: 0 | H208: 0
A210: Adjustments (0)
A211: Manual hour corrections recorded in the legacy weekly file.
B212: Name | C212: Type | D212: Value
A214: Category totals
A215: Sum of hours by work category for this week (SUMIFS from employee rows above).
B216: Category | D216: Basic hours | E216: Mon–Fri overtime | F216: Sat/Sun overtime | G216: Annual holiday | H216: Total paid hours
B217: CLNR | D217: =SUMIFS($D$7:$D$208,$B$7:$B$208,$B217) | E217: =SUMIFS($E$7:$E$208,$B$7:$B$208,$B217) | F217: =SUMIFS($F$7:$F$208,$B$7:$B$208,$B217) | G217: =SUMIFS($G$7:$G$208,$B$7:$B$208,$B217) | H217: =SUMIFS($H$7:$H$208,$B$7:$B$208,$B217)
B218: DPCH | D218: =SUMIFS($D$7:$D$208,$B$7:$B$208,$B218) | E218: =SUMIFS($E$7:$E$208,$B$7:$B$208,$B218) | F218: =SUMIFS($F$7:$F$208,$B$7:$B$208,$B218) | G218: =SUMIFS($G$7:$G$208,$B$7:$B$208,$B218) | H218: =SUMIFS($H$7:$H$208,$B$7:$B$208,$B218)
B219: OFCE | D219: =SUMIFS($D$7:$D$208,$B$7:$B$208,$B219) | E219: =SUMIFS($E$7:$E$208,$B$7:$B$208,$B219) | F219: =SUMIFS($F$7:$F$208,$B$7:$B$208,$B219) | G219: =SUMIFS($G$7:$G$208,$B$7:$B$208,$B219) | H219: =SUMIFS($H$7:$H$208,$B$7:$B$208,$B219)
B220: PKNG HIGH_RISK | D220: =SUMIFS($D$7:$D$208,$B$7:$B$208,$B220) | E220: =SUMIFS($E$7:$E$208,$B$7:$B$208,$B220) | F220: =SUMIFS($F$7:$F$208,$B$7:$B$208,$B220) | G220: =SUMIFS($G$7:$G$208,$B$7:$B$208,$B220) | H220: =SUMIFS($H$7:$H$208,$B$7:$B$208,$B220)
B221: PKNG SLEEVING | D221: =SUMIFS($D$7:$D$208,$B$7:$B$208,$B221) | E221: =SUMIFS($E$7:$E$208,$B$7:$B$208,$B221) | F221: =SUMIFS($F$7:$F$208,$B$7:$B$208,$B221) | G221: =SUMIFS($G$7:$G$208,$B$7:$B$208,$B221) | H221: =SUMIFS($H$7:$H$208,$B$7:$B$208,$B221)
B222: PROD BELT | D222: =SUMIFS($D$7:$D$208,$B$7:$B$208,$B222) | E222: =SUMIFS($E$7:$E$208,$B$7:$B$208,$B222) | F222: =SUMIFS($F$7:$F$208,$B$7:$B$208,$B222) | G222: =SUMIFS($G$7:$G$208,$B$7:$B$208,$B222) | H222: =SUMIFS($H$7:$H$208,$B$7:$B$208,$B222)
B223: PROD FORMING | D223: =SUMIFS($D$7:$D$208,$B$7:$B$208,$B223) | E223: =SUMIFS($E$7:$E$208,$B$7:$B$208,$B223) | F223: =SUMIFS($F$7:$F$208,$B$7:$B$208,$B223) | G223: =SUMIFS($G$7:$G$208,$B$7:$B$208,$B223) | H223: =SUMIFS($H$7:$H$208,$B$7:$B$208,$B223)
B224: PROD FRYING | D224: =SUMIFS($D$7:$D$208,$B$7:$B$208,$B224) | E224: =SUMIFS($E$7:$E$208,$B$7:$B$208,$B224) | F224: =SUMIFS($F$7:$F$208,$B$7:$B$208,$B224) | G224: =SUMIFS($G$7:$G$208,$B$7:$B$208,$B224) | H224: =SUMIFS($H$7:$H$208,$B$7:$B$208,$B224)
B225: PROD PREPARATION | D225: =SUMIFS($D$7:$D$208,$B$7:$B$208,$B225) | E225: =SUMIFS($E$7:$E$208,$B$7:$B$208,$B225) | F225: =SUMIFS($F$7:$F$208,$B$7:$B$208,$B225) | G225: =SUMIFS($G$7:$G$208,$B$7:$B$208,$B225) | H225: =SUMIFS($H$7:$H$208,$B$7:$B$208,$B225)
B226: PROD TABLE | D226: =SUMIFS($D$7:$D$208,$B$7:$B$208,$B226) | E226: =SUMIFS($E$7:$E$208,$B$7:$B$208,$B226) | F226: =SUMIFS($F$7:$F$208,$B$7:$B$208,$B226) | G226: =SUMIFS($G$7:$G$208,$B$7:$B$208,$B226) | H226: =SUMIFS($H$7:$H$208,$B$7:$B$208,$B226)
B227: TECH TECHNICAL | D227: =SUMIFS($D$7:$D$208,$B$7:$B$208,$B227) | E227: =SUMIFS($E$7:$E$208,$B$7:$B$208,$B227) | F227: =SUMIFS($F$7:$F$208,$B$7:$B$208,$B227) | G227: =SUMIFS($G$7:$G$208,$B$7:$B$208,$B227) | H227: =SUMIFS($H$7:$H$208,$B$7:$B$208,$B227)
B228: WRHS | D228: =SUMIFS($D$7:$D$208,$B$7:$B$208,$B228) | E228: =SUMIFS($E$7:$E$208,$B$7:$B$208,$B228) | F228: =SUMIFS($F$7:$F$208,$B$7:$B$208,$B228) | G228: =SUMIFS($G$7:$G$208,$B$7:$B$208,$B228) | H228: =SUMIFS($H$7:$H$208,$B$7:$B$208,$B228)
... B242: A-RS PROD FRYING | D242: =SUMIFS($D$7:$D$208,$B$7:$B$208,$B242) | E242: =SUMIFS($E$7:$E$208,$B$7:$B$208,$B242) | F242: =SUMIFS($F$7:$F$208,$B$7:$B$208,$B242) | G242: =SUMIFS($G$7:$G$208,$B$7:$B$208,$B242) | H242: =SUMIFS($H$7:$H$208,$B$7:$B$208,$B242)
A244: Grouped totals (by category prefix)
A245: Categories rolled up to 4-character groups.
B246: Category | D246: Basic hours | E246: Mon–Fri overtime | F246: Sat/Sun overtime | G246: Annual holiday | H246: Total paid hours
...

Sheet Week4
A1: Gazebo HR — Week 4
A2: Period: D 11/05/2026 to D 17/05/2026
A4: Week 4 — Employee paid hours
A5: One row per employee for this pay week (from weekly export).
A6: Name | B6: Category | C6: Pay ID (Sage) | D6: Basic hours | E6: Mon–Fri overtime | F6: Sat/Sun overtime | G6: Annual holiday | H6: Total paid hours
A7: K CARSANE | B7: CLNR | C7: 692 | D7: 39.75 | E7: 0 | F7: 0 | G7: 0 | H7: 39.75
A8: D GIVA | B8: CLNR | C8: 718 | D8: 30.75 | E8: 6 | F8: 0 | G8: 0 | H8: 36.75
A9: D KUMAR NARANBHAI RATHOD | B9: CLNR | C9: 629 | D9: 40.25 | E9: 0 | F9: 0 | G9: 0 | H9: 40.25
A10: D NATU | B10: CLNR | C10: 750 | D10: 39.75 | E10: 6.75 | F10: 0 | G10: 0 | H10: 46.5
A11: S NATU | B11: CLNR | C11: 579 | D11: 0 | E11: 9.25 | F11: 8.5 | G11: 0 | H11: 17.75
A12: T TIRKEY | B12: CLNR | C12: 506 | D12: 36 | E12: 6 | F12: 0 | G12: 0 | H12: 42
A13: U VINAYCHANDRA | B13: DPCH | C13: 426 | D13: 41.25 | E13: 24.25 | F13: 0 | G13: 0 | H13: 65.5
A14: S BHIMJI VAGADIYA | B14: OFCE | C14: 749 | D14: 20 | E14: 0 | F14: 0 | G14: 0 | H14: 20
A15: D DEVUSINH BAROT | B15: OFCE | C15: 752 | D15: 0 | E15: 0 | F15: 0 | G15: 0 | H15: 0
A16: B DIKER | B16: OFCE | C16: 747 | D16: 41.25 | E16: 5.5 | F16: 0 | G16: 0 | H16: 46.75
A17: U GOHEL | B17: OFCE | C17: 691 | D17: 0 | E17: 8 | F17: 0 | G17: 0 | H17: 8
A18: P LEITE | B18: OFCE | C18: 504 | D18: 41.25 | E18: 4.25 | F18: 0 | G18: 0 | H18: 45.5
... A212: A DABGAR RESPONSE | B212: A-RS PROD FRYING | C212: 0 | D212: 0 | E212: 0 | F212: 0 | G212: 0 | H212: 0
A214: Adjustments (0)
A215: Manual hour corrections recorded in the legacy weekly file.
B216: Name | C216: Type | D216: Value
A218: Category totals
A219: Sum of hours by work category for this week (SUMIFS from employee rows above).
B220: Category | D220: Basic hours | E220: Mon–Fri overtime | F220: Sat/Sun overtime | G220: Annual holiday | H220: Total paid hours
B221: CLNR | D221: =SUMIFS($D$7:$D$212,$B$7:$B$212,$B221) | E221: =SUMIFS($E$7:$E$212,$B$7:$B$212,$B221) | F221: =SUMIFS($F$7:$F$212,$B$7:$B$212,$B221) | G221: =SUMIFS($G$7:$G$212,$B$7:$B$212,$B221) | H221: =SUMIFS($H$7:$H$212,$B$7:$B$212,$B221)
B222: DPCH | D222: =SUMIFS($D$7:$D$212,$B$7:$B$212,$B222) | E222: =SUMIFS($E$7:$E$212,$B$7:$B$212,$B222) | F222: =SUMIFS($F$7:$F$212,$B$7:$B$212,$B222) | G222: =SUMIFS($G$7:$G$212,$B$7:$B$212,$B222) | H222: =SUMIFS($H$7:$H$212,$B$7:$B$212,$B222)
B223: OFCE | D223: =SUMIFS($D$7:$D$212,$B$7:$B$212,$B223) | E223: =SUMIFS($E$7:$E$212,$B$7:$B$212,$B223) | F223: =SUMIFS($F$7:$F$212,$B$7:$B$212,$B223) | G223: =SUMIFS($G$7:$G$212,$B$7:$B$212,$B223) | H223: =SUMIFS($H$7:$H$212,$B$7:$B$212,$B223)
B224: PKNG HIGH_RISK | D224: =SUMIFS($D$7:$D$212,$B$7:$B$212,$B224) | E224: =SUMIFS($E$7:$E$212,$B$7:$B$212,$B224) | F224: =SUMIFS($F$7:$F$212,$B$7:$B$212,$B224) | G224: =SUMIFS($G$7:$G$212,$B$7:$B$212,$B224) | H224: =SUMIFS($H$7:$H$212,$B$7:$B$212,$B224)
B225: PKNG SLEEVING | D225: =SUMIFS($D$7:$D$212,$B$7:$B$212,$B225) | E225: =SUMIFS($E$7:$E$212,$B$7:$B$212,$B225) | F225: =SUMIFS($F$7:$F$212,$B$7:$B$212,$B225) | G225: =SUMIFS($G$7:$G$212,$B$7:$B$212,$B225) | H225: =SUMIFS($H$7:$H$212,$B$7:$B$212,$B225)
B226: PROD BELT | D226: =SUMIFS($D$7:$D$212,$B$7:$B$212,$B226) | E226: =SUMIFS($E$7:$E$212,$B$7:$B$212,$B226) | F226: =SUMIFS($F$7:$F$212,$B$7:$B$212,$B226) | G226: =SUMIFS($G$7:$G$212,$B$7:$B$212,$B226) | H226: =SUMIFS($H$7:$H$212,$B$7:$B$212,$B226)
B227: PROD FORMING | D227: =SUMIFS($D$7:$D$212,$B$7:$B$212,$B227) | E227: =SUMIFS($E$7:$E$212,$B$7:$B$212,$B227) | F227: =SUMIFS($F$7:$F$212,$B$7:$B$212,$B227) | G227: =SUMIFS($G$7:$G$212,$B$7:$B$212,$B227) | H227: =SUMIFS($H$7:$H$212,$B$7:$B$212,$B227)
B228: PROD FRYING | D228: =SUMIFS($D$7:$D$212,$B$7:$B$212,$B228) | E228: =SUMIFS($E$7:$E$212,$B$7:$B$212,$B228) | F228: =SUMIFS($F$7:$F$212,$B$7:$B$212,$B228) | G228: =SUMIFS($G$7:$G$212,$B$7:$B$212,$B228) | H228: =SUMIFS($H$7:$H$212,$B$7:$B$212,$B228)
B229: PROD PREPARATION | D229: =SUMIFS($D$7:$D$212,$B$7:$B$212,$B229) | E229: =SUMIFS($E$7:$E$212,$B$7:$B$212,$B229) | F229: =SUMIFS($F$7:$F$212,$B$7:$B$212,$B229) | G229: =SUMIFS($G$7:$G$212,$B$7:$B$212,$B229) | H229: =SUMIFS($H$7:$H$212,$B$7:$B$212,$B229)
B230: PROD TABLE | D230: =SUMIFS($D$7:$D$212,$B$7:$B$212,$B230) | E230: =SUMIFS($E$7:$E$212,$B$7:$B$212,$B230) | F230: =SUMIFS($F$7:$F$212,$B$7:$B$212,$B230) | G230: =SUMIFS($G$7:$G$212,$B$7:$B$212,$B230) | H230: =SUMIFS($H$7:$H$212,$B$7:$B$212,$B230)
B231: TECH TECHNICAL | D231: =SUMIFS($D$7:$D$212,$B$7:$B$212,$B231) | E231: =SUMIFS($E$7:$E$212,$B$7:$B$212,$B231) | F231: =SUMIFS($F$7:$F$212,$B$7:$B$212,$B231) | G231: =SUMIFS($G$7:$G$212,$B$7:$B$212,$B231) | H231: =SUMIFS($H$7:$H$212,$B$7:$B$212,$B231)
B232: WRHS | D232: =SUMIFS($D$7:$D$212,$B$7:$B$212,$B232) | E232: =SUMIFS($E$7:$E$212,$B$7:$B$212,$B232) | F232: =SUMIFS($F$7:$F$212,$B$7:$B$212,$B232) | G232: =SUMIFS($G$7:$G$212,$B$7:$B$212,$B232) | H232: =SUMIFS($H$7:$H$212,$B$7:$B$212,$B232)
... B246: A-RS PROD FRYING | D246: =SUMIFS($D$7:$D$212,$B$7:$B$212,$B246) | E246: =SUMIFS($E$7:$E$212,$B$7:$B$212,$B246) | F246: =SUMIFS($F$7:$F$212,$B$7:$B$212,$B246) | G246: =SUMIFS($G$7:$G$212,$B$7:$B$212,$B246) | H246: =SUMIFS($H$7:$H$212,$B$7:$B$212,$B246)
A248: Grouped totals (by category prefix)
A249: Categories rolled up to 4-character groups.
B250: Category | D250: Basic hours | E250: Mon–Fri overtime | F250: Sat/Sun overtime | G250: Annual holiday | H250: Total paid hours
...

Sheet Summary
A1: Gazebo HR — Monthly Summary
A2: Period: D 20/04/2026 to D 17/05/2026
A4: Monthly summary — all employees (weeks combined)
A5: Total paid hours per employee across all uploaded weeks. Totals use Excel formulas — click any hour cell to see Week sheet references.
A6: Name | B6: Category | C6: Pay ID (Sage) | D6: Basic hours | E6: Mon–Fri overtime | F6: Sat/Sun overtime | G6: Annual holiday | H6: Total paid hours
A7: K CARSANE | B7: CLNR | C7: 692 | D7: =SUMIF('Week1'!$A:$A,$A7,'Week1'!$D:$D)+SUMIF('Week2'!$A:$A,$A7,'Week2'!$D:$D)+SUMIF('Week3'!$A:$A,$A7,'Week3'!$D:$D)+SUMIF('Week4'!$A:$A,$A7,'Week4'!$D:$D) | E7: =SUMIF('Week1'!$A:$A,$A7,'Week1'!$E:$E)+SUMIF('Week2'!$A:$A,$A7,'Week2'!$E:$E)+SUMIF('Week3'!$A:$A,$A7,'Week3'!$E:$E)+SUMIF('Week4'!$A:$A,$A7,'Week4'!$E:$E) | F7: =SUMIF('Week1'!$A:$A,$A7,'Week1'!$F:$F)+SUMIF('Week2'!$A:$A,$A7,'Week2'!$F:$F)+SUMIF('Week3'!$A:$A,$A7,'Week3'!$F:$F)+SUMIF('Week4'!$A:$A,$A7,'Week4'!$F:$F) | G7: =SUMIF('Week1'!$A:$A,$A7,'Week1'!$G:$G)+SUMIF('Week2'!$A:$A,$A7,'Week2'!$G:$G)+SUMIF('Week3'!$A:$A,$A7,'Week3'!$G:$G)+SUMIF('Week4'!$A:$A,$A7,'Week4'!$G:$G) | H7: =SUMIF('Week1'!$A:$A,$A7,'Week1'!$H:$H)+SUMIF('Week2'!$A:$A,$A7,'Week2'!$H:$H)+SUMIF('Week3'!$A:$A,$A7,'Week3'!$H:$H)+SUMIF('Week4'!$A:$A,$A7,'Week4'!$H:$H)
A8: D GIVA | B8: CLNR | C8: 718 | D8: =SUMIF('Week1'!$A:$A,$A8,'Week1'!$D:$D)+SUMIF('Week2'!$A:$A,$A8,'Week2'!$D:$D)+SUMIF('Week3'!$A:$A,$A8,'Week3'!$D:$D)+SUMIF('Week4'!$A:$A,$A8,'Week4'!$D:$D) | E8: =SUMIF('Week1'!$A:$A,$A8,'Week1'!$E:$E)+SUMIF('Week2'!$A:$A,$A8,'Week2'!$E:$E)+SUMIF('Week3'!$A:$A,$A8,'Week3'!$E:$E)+SUMIF('Week4'!$A:$A,$A8,'Week4'!$E:$E) | F8: =SUMIF('Week1'!$A:$A,$A8,'Week1'!$F:$F)+SUMIF('Week2'!$A:$A,$A8,'Week2'!$F:$F)+SUMIF('Week3'!$A:$A,$A8,'Week3'!$F:$F)+SUMIF('Week4'!$A:$A,$A8,'Week4'!$F:$F) | G8: =SUMIF('Week1'!$A:$A,$A8,'Week1'!$G:$G)+SUMIF('Week2'!$A:$A,$A8,'Week2'!$G:$G)+SUMIF('Week3'!$A:$A,$A8,'Week3'!$G:$G)+SUMIF('Week4'!$A:$A,$A8,'Week4'!$G:$G) | H8: =SUMIF('Week1'!$A:$A,$A8,'Week1'!$H:$H)+SUMIF('Week2'!$A:$A,$A8,'Week2'!$H:$H)+SUMIF('Week3'!$A:$A,$A8,'Week3'!$H:$H)+SUMIF('Week4'!$A:$A,$A8,'Week4'!$H:$H)
A9: D KUMAR NARANBHAI RATHOD | B9: CLNR | C9: 629 | D9: =SUMIF('Week1'!$A:$A,$A9,'Week1'!$D:$D)+SUMIF('Week2'!$A:$A,$A9,'Week2'!$D:$D)+SUMIF('Week3'!$A:$A,$A9,'Week3'!$D:$D)+SUMIF('Week4'!$A:$A,$A9,'Week4'!$D:$D) | E9: =SUMIF('Week1'!$A:$A,$A9,'Week1'!$E:$E)+SUMIF('Week2'!$A:$A,$A9,'Week2'!$E:$E)+SUMIF('Week3'!$A:$A,$A9,'Week3'!$E:$E)+SUMIF('Week4'!$A:$A,$A9,'Week4'!$E:$E) | F9: =SUMIF('Week1'!$A:$A,$A9,'Week1'!$F:$F)+SUMIF('Week2'!$A:$A,$A9,'Week2'!$F:$F)+SUMIF('Week3'!$A:$A,$A9,'Week3'!$F:$F)+SUMIF('Week4'!$A:$A,$A9,'Week4'!$F:$F) | G9: =SUMIF('Week1'!$A:$A,$A9,'Week1'!$G:$G)+SUMIF('Week2'!$A:$A,$A9,'Week2'!$G:$G)+SUMIF('Week3'!$A:$A,$A9,'Week3'!$G:$G)+SUMIF('Week4'!$A:$A,$A9,'Week4'!$G:$G) | H9: =SUMIF('Week1'!$A:$A,$A9,'Week1'!$H:$H)+SUMIF('Week2'!$A:$A,$A9,'Week2'!$H:$H)+SUMIF('Week3'!$A:$A,$A9,'Week3'!$H:$H)+SUMIF('Week4'!$A:$A,$A9,'Week4'!$H:$H)
A10: D NATU | B10: CLNR | C10: 750 | D10: =SUMIF('Week1'!$A:$A,$A10,'Week1'!$D:$D)+SUMIF('Week2'!$A:$A,$A10,'Week2'!$D:$D)+SUMIF('Week3'!$A:$A,$A10,'Week3'!$D:$D)+SUMIF('Week4'!$A:$A,$A10,'Week4'!$D:$D) | E10: =SUMIF('Week1'!$A:$A,$A10,'Week1'!$E:$E)+SUMIF('Week2'!$A:$A,$A10,'Week2'!$E:$E)+SUMIF('Week3'!$A:$A,$A10,'Week3'!$E:$E)+SUMIF('Week4'!$A:$A,$A10,'Week4'!$E:$E) | F10: =SUMIF('Week1'!$A:$A,$A10,'Week1'!$F:$F)+SUMIF('Week2'!$A:$A,$A10,'Week2'!$F:$F)+SUMIF('Week3'!$A:$A,$A10,'Week3'!$F:$F)+SUMIF('Week4'!$A:$A,$A10,'Week4'!$F:$F) | G10: =SUMIF('Week1'!$A:$A,$A10,'Week1'!$G:$G)+SUMIF('Week2'!$A:$A,$A10,'Week2'!$G:$G)+SUMIF('Week3'!$A:$A,$A10,'Week3'!$G:$G)+SUMIF('Week4'!$A:$A,$A10,'Week4'!$G:$G) | H10: =SUMIF('Week1'!$A:$A,$A10,'Week1'!$H:$H)+SUMIF('Week2'!$A:$A,$A10,'Week2'!$H:$H)+SUMIF('Week3'!$A:$A,$A10,'Week3'!$H:$H)+SUMIF('Week4'!$A:$A,$A10,'Week4'!$H:$H)
A11: S NATU | B11: CLNR | C11: 579 | D11: =SUMIF('Week1'!$A:$A,$A11,'Week1'!$D:$D)+SUMIF('Week2'!$A:$A,$A11,'Week2'!$D:$D)+SUMIF('Week3'!$A:$A,$A11,'Week3'!$D:$D)+SUMIF('Week4'!$A:$A,$A11,'Week4'!$D:$D) | E11: =SUMIF('Week1'!$A:$A,$A11,'Week1'!$E:$E)+SUMIF('Week2'!$A:$A,$A11,'Week2'!$E:$E)+SUMIF('Week3'!$A:$A,$A11,'Week3'!$E:$E)+SUMIF('Week4'!$A:$A,$A11,'Week4'!$E:$E) | F11: =SUMIF('Week1'!$A:$A,$A11,'Week1'!$F:$F)+SUMIF('Week2'!$A:$A,$A11,'Week2'!$F:$F)+SUMIF('Week3'!$A:$A,$A11,'Week3'!$F:$F)+SUMIF('Week4'!$A:$A,$A11,'Week4'!$F:$F) | G11: =SUMIF('Week1'!$A:$A,$A11,'Week1'!$G:$G)+SUMIF('Week2'!$A:$A,$A11,'Week2'!$G:$G)+SUMIF('Week3'!$A:$A,$A11,'Week3'!$G:$G)+SUMIF('Week4'!$A:$A,$A11,'Week4'!$G:$G) | H11: =SUMIF('Week1'!$A:$A,$A11,'Week1'!$H:$H)+SUMIF('Week2'!$A:$A,$A11,'Week2'!$H:$H)+SUMIF('Week3'!$A:$A,$A11,'Week3'!$H:$H)+SUMIF('Week4'!$A:$A,$A11,'Week4'!$H:$H)
A12: T TIRKEY | B12: CLNR | C12: 506 | D12: =SUMIF('Week1'!$A:$A,$A12,'Week1'!$D:$D)+SUMIF('Week2'!$A:$A,$A12,'Week2'!$D:$D)+SUMIF('Week3'!$A:$A,$A12,'Week3'!$D:$D)+SUMIF('Week4'!$A:$A,$A12,'Week4'!$D:$D) | E12: =SUMIF('Week1'!$A:$A,$A12,'Week1'!$E:$E)+SUMIF('Week2'!$A:$A,$A12,'Week2'!$E:$E)+SUMIF('Week3'!$A:$A,$A12,'Week3'!$E:$E)+SUMIF('Week4'!$A:$A,$A12,'Week4'!$E:$E) | F12: =SUMIF('Week1'!$A:$A,$A12,'Week1'!$F:$F)+SUMIF('Week2'!$A:$A,$A12,'Week2'!$F:$F)+SUMIF('Week3'!$A:$A,$A12,'Week3'!$F:$F)+SUMIF('Week4'!$A:$A,$A12,'Week4'!$F:$F) | G12: =SUMIF('Week1'!$A:$A,$A12,'Week1'!$G:$G)+SUMIF('Week2'!$A:$A,$A12,'Week2'!$G:$G)+SUMIF('Week3'!$A:$A,$A12,'Week3'!$G:$G)+SUMIF('Week4'!$A:$A,$A12,'Week4'!$G:$G) | H12: =SUMIF('Week1'!$A:$A,$A12,'Week1'!$H:$H)+SUMIF('Week2'!$A:$A,$A12,'Week2'!$H:$H)+SUMIF('Week3'!$A:$A,$A12,'Week3'!$H:$H)+SUMIF('Week4'!$A:$A,$A12,'Week4'!$H:$H)
A13: U VINAYCHANDRA | B13: DPCH | C13: 426 | D13: =SUMIF('Week1'!$A:$A,$A13,'Week1'!$D:$D)+SUMIF('Week2'!$A:$A,$A13,'Week2'!$D:$D)+SUMIF('Week3'!$A:$A,$A13,'Week3'!$D:$D)+SUMIF('Week4'!$A:$A,$A13,'Week4'!$D:$D) | E13: =SUMIF('Week1'!$A:$A,$A13,'Week1'!$E:$E)+SUMIF('Week2'!$A:$A,$A13,'Week2'!$E:$E)+SUMIF('Week3'!$A:$A,$A13,'Week3'!$E:$E)+SUMIF('Week4'!$A:$A,$A13,'Week4'!$E:$E) | F13: =SUMIF('Week1'!$A:$A,$A13,'Week1'!$F:$F)+SUMIF('Week2'!$A:$A,$A13,'Week2'!$F:$F)+SUMIF('Week3'!$A:$A,$A13,'Week3'!$F:$F)+SUMIF('Week4'!$A:$A,$A13,'Week4'!$F:$F) | G13: =SUMIF('Week1'!$A:$A,$A13,'Week1'!$G:$G)+SUMIF('Week2'!$A:$A,$A13,'Week2'!$G:$G)+SUMIF('Week3'!$A:$A,$A13,'Week3'!$G:$G)+SUMIF('Week4'!$A:$A,$A13,'Week4'!$G:$G) | H13: =SUMIF('Week1'!$A:$A,$A13,'Week1'!$H:$H)+SUMIF('Week2'!$A:$A,$A13,'Week2'!$H:$H)+SUMIF('Week3'!$A:$A,$A13,'Week3'!$H:$H)+SUMIF('Week4'!$A:$A,$A13,'Week4'!$H:$H)
A14: S BHIMJI VAGADIYA | B14: OFCE | C14: 749 | D14: =SUMIF('Week1'!$A:$A,$A14,'Week1'!$D:$D)+SUMIF('Week2'!$A:$A,$A14,'Week2'!$D:$D)+SUMIF('Week3'!$A:$A,$A14,'Week3'!$D:$D)+SUMIF('Week4'!$A:$A,$A14,'Week4'!$D:$D) | E14: =SUMIF('Week1'!$A:$A,$A14,'Week1'!$E:$E)+SUMIF('Week2'!$A:$A,$A14,'Week2'!$E:$E)+SUMIF('Week3'!$A:$A,$A14,'Week3'!$E:$E)+SUMIF('Week4'!$A:$A,$A14,'Week4'!$E:$E) | F14: =SUMIF('Week1'!$A:$A,$A14,'Week1'!$F:$F)+SUMIF('Week2'!$A:$A,$A14,'Week2'!$F:$F)+SUMIF('Week3'!$A:$A,$A14,'Week3'!$F:$F)+SUMIF('Week4'!$A:$A,$A14,'Week4'!$F:$F) | G14: =SUMIF('Week1'!$A:$A,$A14,'Week1'!$G:$G)+SUMIF('Week2'!$A:$A,$A14,'Week2'!$G:$G)+SUMIF('Week3'!$A:$A,$A14,'Week3'!$G:$G)+SUMIF('Week4'!$A:$A,$A14,'Week4'!$G:$G) | H14: =SUMIF('Week1'!$A:$A,$A14,'Week1'!$H:$H)+SUMIF('Week2'!$A:$A,$A14,'Week2'!$H:$H)+SUMIF('Week3'!$A:$A,$A14,'Week3'!$H:$H)+SUMIF('Week4'!$A:$A,$A14,'Week4'!$H:$H)
A15: D DEVUSINH BAROT | B15: OFCE | C15: 752 | D15: =SUMIF('Week1'!$A:$A,$A15,'Week1'!$D:$D)+SUMIF('Week2'!$A:$A,$A15,'Week2'!$D:$D)+SUMIF('Week3'!$A:$A,$A15,'Week3'!$D:$D)+SUMIF('Week4'!$A:$A,$A15,'Week4'!$D:$D) | E15: =SUMIF('Week1'!$A:$A,$A15,'Week1'!$E:$E)+SUMIF('Week2'!$A:$A,$A15,'Week2'!$E:$E)+SUMIF('Week3'!$A:$A,$A15,'Week3'!$E:$E)+SUMIF('Week4'!$A:$A,$A15,'Week4'!$E:$E) | F15: =SUMIF('Week1'!$A:$A,$A15,'Week1'!$F:$F)+SUMIF('Week2'!$A:$A,$A15,'Week2'!$F:$F)+SUMIF('Week3'!$A:$A,$A15,'Week3'!$F:$F)+SUMIF('Week4'!$A:$A,$A15,'Week4'!$F:$F) | G15: =SUMIF('Week1'!$A:$A,$A15,'Week1'!$G:$G)+SUMIF('Week2'!$A:$A,$A15,'Week2'!$G:$G)+SUMIF('Week3'!$A:$A,$A15,'Week3'!$G:$G)+SUMIF('Week4'!$A:$A,$A15,'Week4'!$G:$G) | H15: =SUMIF('Week1'!$A:$A,$A15,'Week1'!$H:$H)+SUMIF('Week2'!$A:$A,$A15,'Week2'!$H:$H)+SUMIF('Week3'!$A:$A,$A15,'Week3'!$H:$H)+SUMIF('Week4'!$A:$A,$A15,'Week4'!$H:$H)
A16: B DIKER | B16: OFCE | C16: 747 | D16: =SUMIF('Week1'!$A:$A,$A16,'Week1'!$D:$D)+SUMIF('Week2'!$A:$A,$A16,'Week2'!$D:$D)+SUMIF('Week3'!$A:$A,$A16,'Week3'!$D:$D)+SUMIF('Week4'!$A:$A,$A16,'Week4'!$D:$D) | E16: =SUMIF('Week1'!$A:$A,$A16,'Week1'!$E:$E)+SUMIF('Week2'!$A:$A,$A16,'Week2'!$E:$E)+SUMIF('Week3'!$A:$A,$A16,'Week3'!$E:$E)+SUMIF('Week4'!$A:$A,$A16,'Week4'!$E:$E) | F16: =SUMIF('Week1'!$A:$A,$A16,'Week1'!$F:$F)+SUMIF('Week2'!$A:$A,$A16,'Week2'!$F:$F)+SUMIF('Week3'!$A:$A,$A16,'Week3'!$F:$F)+SUMIF('Week4'!$A:$A,$A16,'Week4'!$F:$F) | G16: =SUMIF('Week1'!$A:$A,$A16,'Week1'!$G:$G)+SUMIF('Week2'!$A:$A,$A16,'Week2'!$G:$G)+SUMIF('Week3'!$A:$A,$A16,'Week3'!$G:$G)+SUMIF('Week4'!$A:$A,$A16,'Week4'!$G:$G) | H16: =SUMIF('Week1'!$A:$A,$A16,'Week1'!$H:$H)+SUMIF('Week2'!$A:$A,$A16,'Week2'!$H:$H)+SUMIF('Week3'!$A:$A,$A16,'Week3'!$H:$H)+SUMIF('Week4'!$A:$A,$A16,'Week4'!$H:$H)
A17: U GOHEL | B17: OFCE | C17: 691 | D17: =SUMIF('Week1'!$A:$A,$A17,'Week1'!$D:$D)+SUMIF('Week2'!$A:$A,$A17,'Week2'!$D:$D)+SUMIF('Week3'!$A:$A,$A17,'Week3'!$D:$D)+SUMIF('Week4'!$A:$A,$A17,'Week4'!$D:$D) | E17: =SUMIF('Week1'!$A:$A,$A17,'Week1'!$E:$E)+SUMIF('Week2'!$A:$A,$A17,'Week2'!$E:$E)+SUMIF('Week3'!$A:$A,$A17,'Week3'!$E:$E)+SUMIF('Week4'!$A:$A,$A17,'Week4'!$E:$E) | F17: =SUMIF('Week1'!$A:$A,$A17,'Week1'!$F:$F)+SUMIF('Week2'!$A:$A,$A17,'Week2'!$F:$F)+SUMIF('Week3'!$A:$A,$A17,'Week3'!$F:$F)+SUMIF('Week4'!$A:$A,$A17,'Week4'!$F:$F) | G17: =SUMIF('Week1'!$A:$A,$A17,'Week1'!$G:$G)+SUMIF('Week2'!$A:$A,$A17,'Week2'!$G:$G)+SUMIF('Week3'!$A:$A,$A17,'Week3'!$G:$G)+SUMIF('Week4'!$A:$A,$A17,'Week4'!$G:$G) | H17: =SUMIF('Week1'!$A:$A,$A17,'Week1'!$H:$H)+SUMIF('Week2'!$A:$A,$A17,'Week2'!$H:$H)+SUMIF('Week3'!$A:$A,$A17,'Week3'!$H:$H)+SUMIF('Week4'!$A:$A,$A17,'Week4'!$H:$H)
A18: P LEITE | B18: OFCE | C18: 504 | D18: =SUMIF('Week1'!$A:$A,$A18,'Week1'!$D:$D)+SUMIF('Week2'!$A:$A,$A18,'Week2'!$D:$D)+SUMIF('Week3'!$A:$A,$A18,'Week3'!$D:$D)+SUMIF('Week4'!$A:$A,$A18,'Week4'!$D:$D) | E18: =SUMIF('Week1'!$A:$A,$A18,'Week1'!$E:$E)+SUMIF('Week2'!$A:$A,$A18,'Week2'!$E:$E)+SUMIF('Week3'!$A:$A,$A18,'Week3'!$E:$E)+SUMIF('Week4'!$A:$A,$A18,'Week4'!$E:$E) | F18: =SUMIF('Week1'!$A:$A,$A18,'Week1'!$F:$F)+SUMIF('Week2'!$A:$A,$A18,'Week2'!$F:$F)+SUMIF('Week3'!$A:$A,$A18,'Week3'!$F:$F)+SUMIF('Week4'!$A:$A,$A18,'Week4'!$F:$F) | G18: =SUMIF('Week1'!$A:$A,$A18,'Week1'!$G:$G)+SUMIF('Week2'!$A:$A,$A18,'Week2'!$G:$G)+SUMIF('Week3'!$A:$A,$A18,'Week3'!$G:$G)+SUMIF('Week4'!$A:$A,$A18,'Week4'!$G:$G) | H18: =SUMIF('Week1'!$A:$A,$A18,'Week1'!$H:$H)+SUMIF('Week2'!$A:$A,$A18,'Week2'!$H:$H)+SUMIF('Week3'!$A:$A,$A18,'Week3'!$H:$H)+SUMIF('Week4'!$A:$A,$A18,'Week4'!$H:$H)
... A211: A VALACU RESPONSE | B211: A-RS PKNG SLEEVING | C211: 0 | D211: =SUMIF('Week1'!$A:$A,$A211,'Week1'!$D:$D)+SUMIF('Week2'!$A:$A,$A211,'Week2'!$D:$D)+SUMIF('Week3'!$A:$A,$A211,'Week3'!$D:$D)+SUMIF('Week4'!$A:$A,$A211,'Week4'!$D:$D) | E211: =SUMIF('Week1'!$A:$A,$A211,'Week1'!$E:$E)+SUMIF('Week2'!$A:$A,$A211,'Week2'!$E:$E)+SUMIF('Week3'!$A:$A,$A211,'Week3'!$E:$E)+SUMIF('Week4'!$A:$A,$A211,'Week4'!$E:$E) | F211: =SUMIF('Week1'!$A:$A,$A211,'Week1'!$F:$F)+SUMIF('Week2'!$A:$A,$A211,'Week2'!$F:$F)+SUMIF('Week3'!$A:$A,$A211,'Week3'!$F:$F)+SUMIF('Week4'!$A:$A,$A211,'Week4'!$F:$F) | G211: =SUMIF('Week1'!$A:$A,$A211,'Week1'!$G:$G)+SUMIF('Week2'!$A:$A,$A211,'Week2'!$G:$G)+SUMIF('Week3'!$A:$A,$A211,'Week3'!$G:$G)+SUMIF('Week4'!$A:$A,$A211,'Week4'!$G:$G) | H211: =SUMIF('Week1'!$A:$A,$A211,'Week1'!$H:$H)+SUMIF('Week2'!$A:$A,$A211,'Week2'!$H:$H)+SUMIF('Week3'!$A:$A,$A211,'Week3'!$H:$H)+SUMIF('Week4'!$A:$A,$A211,'Week4'!$H:$H)
A213: Category totals (month)
A214: Sum of hours by work category — calculated with SUMIFS from the employee table above.
B215: Category | D215: Basic hours | E215: Mon–Fri overtime | F215: Sat/Sun overtime | G215: Annual holiday | H215: Total paid hours
B216: CLNR | D216: =SUMIFS($D$7:$D$211,$B$7:$B$211,$B216) | E216: =SUMIFS($E$7:$E$211,$B$7:$B$211,$B216) | F216: =SUMIFS($F$7:$F$211,$B$7:$B$211,$B216) | G216: =SUMIFS($G$7:$G$211,$B$7:$B$211,$B216) | H216: =SUMIFS($H$7:$H$211,$B$7:$B$211,$B216)
B217: DPCH | D217: =SUMIFS($D$7:$D$211,$B$7:$B$211,$B217) | E217: =SUMIFS($E$7:$E$211,$B$7:$B$211,$B217) | F217: =SUMIFS($F$7:$F$211,$B$7:$B$211,$B217) | G217: =SUMIFS($G$7:$G$211,$B$7:$B$211,$B217) | H217: =SUMIFS($H$7:$H$211,$B$7:$B$211,$B217)
B218: OFCE | D218: =SUMIFS($D$7:$D$211,$B$7:$B$211,$B218) | E218: =SUMIFS($E$7:$E$211,$B$7:$B$211,$B218) | F218: =SUMIFS($F$7:$F$211,$B$7:$B$211,$B218) | G218: =SUMIFS($G$7:$G$211,$B$7:$B$211,$B218) | H218: =SUMIFS($H$7:$H$211,$B$7:$B$211,$B218)
B219: PKNG HIGH_RISK | D219: =SUMIFS($D$7:$D$211,$B$7:$B$211,$B219) | E219: =SUMIFS($E$7:$E$211,$B$7:$B$211,$B219) | F219: =SUMIFS($F$7:$F$211,$B$7:$B$211,$B219) | G219: =SUMIFS($G$7:$G$211,$B$7:$B$211,$B219) | H219: =SUMIFS($H$7:$H$211,$B$7:$B$211,$B219)
B220: PKNG SLEEVING | D220: =SUMIFS($D$7:$D$211,$B$7:$B$211,$B220) | E220: =SUMIFS($E$7:$E$211,$B$7:$B$211,$B220) | F220: =SUMIFS($F$7:$F$211,$B$7:$B$211,$B220) | G220: =SUMIFS($G$7:$G$211,$B$7:$B$211,$B220) | H220: =SUMIFS($H$7:$H$211,$B$7:$B$211,$B220)
B221: PROD BELT | D221: =SUMIFS($D$7:$D$211,$B$7:$B$211,$B221) | E221: =SUMIFS($E$7:$E$211,$B$7:$B$211,$B221) | F221: =SUMIFS($F$7:$F$211,$B$7:$B$211,$B221) | G221: =SUMIFS($G$7:$G$211,$B$7:$B$211,$B221) | H221: =SUMIFS($H$7:$H$211,$B$7:$B$211,$B221)
B222: PROD FORMING | D222: =SUMIFS($D$7:$D$211,$B$7:$B$211,$B222) | E222: =SUMIFS($E$7:$E$211,$B$7:$B$211,$B222) | F222: =SUMIFS($F$7:$F$211,$B$7:$B$211,$B222) | G222: =SUMIFS($G$7:$G$211,$B$7:$B$211,$B222) | H222: =SUMIFS($H$7:$H$211,$B$7:$B$211,$B222)
B223: PROD FRYING | D223: =SUMIFS($D$7:$D$211,$B$7:$B$211,$B223) | E223: =SUMIFS($E$7:$E$211,$B$7:$B$211,$B223) | F223: =SUMIFS($F$7:$F$211,$B$7:$B$211,$B223) | G223: =SUMIFS($G$7:$G$211,$B$7:$B$211,$B223) | H223: =SUMIFS($H$7:$H$211,$B$7:$B$211,$B223)
B224: PROD PREPARATION | D224: =SUMIFS($D$7:$D$211,$B$7:$B$211,$B224) | E224: =SUMIFS($E$7:$E$211,$B$7:$B$211,$B224) | F224: =SUMIFS($F$7:$F$211,$B$7:$B$211,$B224) | G224: =SUMIFS($G$7:$G$211,$B$7:$B$211,$B224) | H224: =SUMIFS($H$7:$H$211,$B$7:$B$211,$B224)
B225: PROD TABLE | D225: =SUMIFS($D$7:$D$211,$B$7:$B$211,$B225) | E225: =SUMIFS($E$7:$E$211,$B$7:$B$211,$B225) | F225: =SUMIFS($F$7:$F$211,$B$7:$B$211,$B225) | G225: =SUMIFS($G$7:$G$211,$B$7:$B$211,$B225) | H225: =SUMIFS($H$7:$H$211,$B$7:$B$211,$B225)
B226: TECH TECHNICAL | D226: =SUMIFS($D$7:$D$211,$B$7:$B$211,$B226) | E226: =SUMIFS($E$7:$E$211,$B$7:$B$211,$B226) | F226: =SUMIFS($F$7:$F$211,$B$7:$B$211,$B226) | G226: =SUMIFS($G$7:$G$211,$B$7:$B$211,$B226) | H226: =SUMIFS($H$7:$H$211,$B$7:$B$211,$B226)
B227: WRHS | D227: =SUMIFS($D$7:$D$211,$B$7:$B$211,$B227) | E227: =SUMIFS($E$7:$E$211,$B$7:$B$211,$B227) | F227: =SUMIFS($F$7:$F$211,$B$7:$B$211,$B227) | G227: =SUMIFS($G$7:$G$211,$B$7:$B$211,$B227) | H227: =SUMIFS($H$7:$H$211,$B$7:$B$211,$B227)
... B241: A-EL WRHS | D241: =SUMIFS($D$7:$D$211,$B$7:$B$211,$B241) | E241: =SUMIFS($E$7:$E$211,$B$7:$B$211,$B241) | F241: =SUMIFS($F$7:$F$211,$B$7:$B$211,$B241) | G241: =SUMIFS($G$7:$G$211,$B$7:$B$211,$B241) | H241: =SUMIFS($H$7:$H$211,$B$7:$B$211,$B241)
A243: Grouped totals (month)
A244: Categories rolled up to 4-character groups across all weeks.
B245: Category | D245: Basic hours | E245: Mon–Fri overtime | F245: Sat/Sun overtime | G245: Annual holiday | H245: Total paid hours
B246: A-EL CLNR | D246: 876 | E246: 49.75 | F246: 10.75 | G246: 0 | H246: 936.5
B247: A-EL DPCH | D247: 135 | E247: 15.25 | F247: 0 | G247: 0 | H247: 150.25
B248: A-EL PKNG | D248: 2623.25 | E248: 58.5 | F248: 20.5 | G248: 0 | H248: 2702.25
...
