Workbook

Sheet Week1
A1: Gazebo HR — Week 1
A4: Week 1 — Employee paid hours
A5: One row per employee for this pay week (from weekly export).
A6: Name | B6: Category | C6: Pay ID (Sage) | D6: Basic hours | E6: Mon–Fri overtime | F6: Sat/Sun overtime | G6: Annual holiday | H6: Total paid hours | I6: Contracted hours | J6: Extra hours | K6: Additional holiday pay
A7: RAMJI BABU EOLL | B7: A-EL CLNR | C7: 1564 | D7: 32.25 | E7: 0 | F7: 0 | G7: 0 | H7: 32.25 | I7: 0 | J7: 32.25 | K7: 3.89
A8: DIPEN BAMANIA EOLL | B8: A-EL CLNR | C8: 1635 | D8: 32 | E8: 7.5 | F8: 0 | G8: 0 | H8: 39.5 | I8: 0 | J8: 39.5 | K8: 4.77
A9: SAVJI CHAGANA EOLL | B9: A-EL CLNR | C9: 1659 | D9: 37 | E9: 7.5 | F9: 0 | G9: 0 | H9: 44.5 | I9: 0 | J9: 44.5 | K9: 5.37
A10: KAMLESH NATVAR EOLL | B10: A-EL CLNR | C10: 1563 | D10: 32 | E10: 0 | F10: 0 | G10: 0 | H10: 32 | I10: 0 | J10: 32 | K10: 3.86
A11: LALJI SOMA EOLL | B11: A-EL CLNR | C11: 1262 | D11: 37.5 | E11: 0 | F11: 0 | G11: 0 | H11: 37.5 | I11: 0 | J11: 37.5 | K11: 4.53
A12: DHANJI VIRA EOLL | B12: A-EL CLNR | C12: 1634 | D12: 22.5 | E12: 0 | F12: 0 | G12: 0 | H12: 22.5 | I12: 0 | J12: 22.5 | K12: 2.72
A13: AJAYKUMAR VIRA EOLL | B13: A-EL DPCH | C13: 1371 | D13: 31 | E13: 6.25 | F13: 0 | G13: 0 | H13: 37.25 | I13: 0 | J13: 37.25 | K13: 4.5
A14: MEGHNABEN GANDHI EOLL | B14: A-EL OFCE | C14: 1668 | D14: 38.25 | E14: 0 | F14: 0 | G14: 0 | H14: 38.25 | I14: 0 | J14: 38.25 | K14: 4.62
A15: KRISHKUMAR BHALALA EOLL | B15: A-EL PKNG HIGH_RISK | C15: 1540 | D15: 0 | E15: 0 | F15: 0 | G15: 0 | H15: 0 | I15: 0 | J15: 0 | K15: 0
A16: SHRUTI BIPINBHAI DOBARIYA EOLL | B16: A-EL PKNG HIGH_RISK | C16: 1640 | D16: 0 | E16: 0 | F16: 0 | G16: 0 | H16: 0 | I16: 0 | J16: 0 | K16: 0
A17: HARESH CHAGAN EOLL | B17: A-EL PKNG HIGH_RISK | C17: 1633 | D17: 0 | E17: 0 | F17: 0 | G17: 0 | H17: 0 | I17: 0 | J17: 0 | K17: 0
A18: ANKIT CHOTALA EOLL | B18: A-EL PKNG HIGH_RISK | C18: 1649 | D18: 0 | E18: 0 | F18: 0 | G18: 0 | H18: 0 | I18: 0 | J18: 0 | K18: 0
... A206: SURENDRAN SUBRAMANI | B206: WRHS | C206: 205 | D206: 37.25 | E206: 0 | F206: 7.75 | G206: 0 | H206: 45 | I206: 0 | J206: 45 | K206: 5.43
A208: Adjustments (0)
A209: Manual hour corrections recorded in the legacy weekly file.
B210: Name | C210: Type | D210: Value
A212: Category totals
A213: Sum of hours by work category for this week (SUMIFS from employee rows above).
B214: Category | D214: Basic hours | E214: Mon–Fri overtime | F214: Sat/Sun overtime | G214: Annual holiday | H214: Total paid hours
B215: A-EL CLNR | D215: =SUMIFS($D$7:$D$206,$B$7:$B$206,$B215) | E215: =SUMIFS($E$7:$E$206,$B$7:$B$206,$B215) | F215: =SUMIFS($F$7:$F$206,$B$7:$B$206,$B215) | G215: =SUMIFS($G$7:$G$206,$B$7:$B$206,$B215) | H215: =SUMIFS($H$7:$H$206,$B$7:$B$206,$B215)
B216: A-EL DPCH | D216: =SUMIFS($D$7:$D$206,$B$7:$B$206,$B216) | E216: =SUMIFS($E$7:$E$206,$B$7:$B$206,$B216) | F216: =SUMIFS($F$7:$F$206,$B$7:$B$206,$B216) | G216: =SUMIFS($G$7:$G$206,$B$7:$B$206,$B216) | H216: =SUMIFS($H$7:$H$206,$B$7:$B$206,$B216)
B217: A-EL OFCE | D217: =SUMIFS($D$7:$D$206,$B$7:$B$206,$B217) | E217: =SUMIFS($E$7:$E$206,$B$7:$B$206,$B217) | F217: =SUMIFS($F$7:$F$206,$B$7:$B$206,$B217) | G217: =SUMIFS($G$7:$G$206,$B$7:$B$206,$B217) | H217: =SUMIFS($H$7:$H$206,$B$7:$B$206,$B217)
B218: A-EL PKNG HIGH_RISK | D218: =SUMIFS($D$7:$D$206,$B$7:$B$206,$B218) | E218: =SUMIFS($E$7:$E$206,$B$7:$B$206,$B218) | F218: =SUMIFS($F$7:$F$206,$B$7:$B$206,$B218) | G218: =SUMIFS($G$7:$G$206,$B$7:$B$206,$B218) | H218: =SUMIFS($H$7:$H$206,$B$7:$B$206,$B218)
B219: A-EL PKNG SLEEVING | D219: =SUMIFS($D$7:$D$206,$B$7:$B$206,$B219) | E219: =SUMIFS($E$7:$E$206,$B$7:$B$206,$B219) | F219: =SUMIFS($F$7:$F$206,$B$7:$B$206,$B219) | G219: =SUMIFS($G$7:$G$206,$B$7:$B$206,$B219) | H219: =SUMIFS($H$7:$H$206,$B$7:$B$206,$B219)
B220: A-EL PROD BELT | D220: =SUMIFS($D$7:$D$206,$B$7:$B$206,$B220) | E220: =SUMIFS($E$7:$E$206,$B$7:$B$206,$B220) | F220: =SUMIFS($F$7:$F$206,$B$7:$B$206,$B220) | G220: =SUMIFS($G$7:$G$206,$B$7:$B$206,$B220) | H220: =SUMIFS($H$7:$H$206,$B$7:$B$206,$B220)
B221: A-EL PROD FORMING | D221: =SUMIFS($D$7:$D$206,$B$7:$B$206,$B221) | E221: =SUMIFS($E$7:$E$206,$B$7:$B$206,$B221) | F221: =SUMIFS($F$7:$F$206,$B$7:$B$206,$B221) | G221: =SUMIFS($G$7:$G$206,$B$7:$B$206,$B221) | H221: =SUMIFS($H$7:$H$206,$B$7:$B$206,$B221)
B222: A-EL PROD FRYING | D222: =SUMIFS($D$7:$D$206,$B$7:$B$206,$B222) | E222: =SUMIFS($E$7:$E$206,$B$7:$B$206,$B222) | F222: =SUMIFS($F$7:$F$206,$B$7:$B$206,$B222) | G222: =SUMIFS($G$7:$G$206,$B$7:$B$206,$B222) | H222: =SUMIFS($H$7:$H$206,$B$7:$B$206,$B222)
B223: A-EL PROD PREPARATION | D223: =SUMIFS($D$7:$D$206,$B$7:$B$206,$B223) | E223: =SUMIFS($E$7:$E$206,$B$7:$B$206,$B223) | F223: =SUMIFS($F$7:$F$206,$B$7:$B$206,$B223) | G223: =SUMIFS($G$7:$G$206,$B$7:$B$206,$B223) | H223: =SUMIFS($H$7:$H$206,$B$7:$B$206,$B223)
B224: A-EL TECHNICAL | D224: =SUMIFS($D$7:$D$206,$B$7:$B$206,$B224) | E224: =SUMIFS($E$7:$E$206,$B$7:$B$206,$B224) | F224: =SUMIFS($F$7:$F$206,$B$7:$B$206,$B224) | G224: =SUMIFS($G$7:$G$206,$B$7:$B$206,$B224) | H224: =SUMIFS($H$7:$H$206,$B$7:$B$206,$B224)
B225: A-EL WRHS | D225: =SUMIFS($D$7:$D$206,$B$7:$B$206,$B225) | E225: =SUMIFS($E$7:$E$206,$B$7:$B$206,$B225) | F225: =SUMIFS($F$7:$F$206,$B$7:$B$206,$B225) | G225: =SUMIFS($G$7:$G$206,$B$7:$B$206,$B225) | H225: =SUMIFS($H$7:$H$206,$B$7:$B$206,$B225)
B226: A-PM PKNG HIGH_RISK | D226: =SUMIFS($D$7:$D$206,$B$7:$B$206,$B226) | E226: =SUMIFS($E$7:$E$206,$B$7:$B$206,$B226) | F226: =SUMIFS($F$7:$F$206,$B$7:$B$206,$B226) | G226: =SUMIFS($G$7:$G$206,$B$7:$B$206,$B226) | H226: =SUMIFS($H$7:$H$206,$B$7:$B$206,$B226)
... B241: WRHS | D241: =SUMIFS($D$7:$D$206,$B$7:$B$206,$B241) | E241: =SUMIFS($E$7:$E$206,$B$7:$B$206,$B241) | F241: =SUMIFS($F$7:$F$206,$B$7:$B$206,$B241) | G241: =SUMIFS($G$7:$G$206,$B$7:$B$206,$B241) | H241: =SUMIFS($H$7:$H$206,$B$7:$B$206,$B241)
A243: Grouped totals (by category prefix)
A244: Categories rolled up to 4-character groups.
B245: Category | D245: Basic hours | E245: Mon–Fri overtime | F245: Sat/Sun overtime | G245: Annual holiday | H245: Total paid hours
B246: A-EL CLNR | D246: 193.25 | E246: 15 | F246: 0 | G246: 0 | H246: 208.25
...

Sheet Week2
A1: Gazebo HR — Week 2
A4: Week 2 — Employee paid hours
A5: One row per employee for this pay week (from weekly export).
A6: Name | B6: Category | C6: Pay ID (Sage) | D6: Basic hours | E6: Mon–Fri overtime | F6: Sat/Sun overtime | G6: Annual holiday | H6: Total paid hours | I6: Contracted hours | J6: Extra hours | K6: Additional holiday pay
A7: RAMJI BABU EOLL | B7: A-EL CLNR | C7: 1564 | D7: 33 | E7: 0 | F7: 0 | G7: 0 | H7: 33 | I7: 0 | J7: 33 | K7: 3.98
A8: KANJI BAGOANE EOLL | B8: A-EL CLNR | C8: 1683 | D8: 0 | E8: 0 | F8: 0 | G8: 0 | H8: 0 | I8: 0 | J8: 0 | K8: 0
A9: VELJI BAGUANE EOLL | B9: A-EL CLNR | C9: 1681 | D9: 0 | E9: 0 | F9: 0 | G9: 0 | H9: 0 | I9: 0 | J9: 0 | K9: 0
A10: DIPEN BAMANIA EOLL | B10: A-EL CLNR | C10: 1635 | D10: 32 | E10: 6.75 | F10: 0 | G10: 0 | H10: 38.75 | I10: 0 | J10: 38.75 | K10: 4.68
A11: SAVJI CHAGANA EOLL | B11: A-EL CLNR | C11: 1659 | D11: 37.25 | E11: 7.5 | F11: 0 | G11: 0 | H11: 44.75 | I11: 0 | J11: 44.75 | K11: 5.4
A12: KIRANKUMAR CHAUDHARY EOLL | B12: A-EL CLNR | C12: 1685 | D12: 0 | E12: 0 | F12: 0 | G12: 0 | H12: 0 | I12: 0 | J12: 0 | K12: 0
A13: HALPATI DHIRAJ RAMAN EOLL | B13: A-EL CLNR | C13: 1670 | D13: 0 | E13: 0 | F13: 0 | G13: 0 | H13: 0 | I13: 0 | J13: 0 | K13: 0
A14: MANN HASMUKHBHAI VIRANI EOLL | B14: A-EL CLNR | C14: 1684 | D14: 0 | E14: 0 | F14: 0 | G14: 0 | H14: 0 | I14: 0 | J14: 0 | K14: 0
A15: KAMLESH NATVAR EOLL | B15: A-EL CLNR | C15: 1563 | D15: 24 | E15: 0 | F15: 0 | G15: 0 | H15: 24 | I15: 0 | J15: 24 | K15: 2.9
A16: LALJI SOMA EOLL | B16: A-EL CLNR | C16: 1262 | D16: 28.5 | E16: 0 | F16: 0 | G16: 0 | H16: 28.5 | I16: 0 | J16: 28.5 | K16: 3.44
A17: DHANJI VIRA EOLL | B17: A-EL CLNR | C17: 1634 | D17: 31.25 | E17: 0 | F17: 0 | G17: 0 | H17: 31.25 | I17: 0 | J17: 31.25 | K17: 3.77
A18: AJAYKUMAR VIRA EOLL | B18: A-EL DPCH | C18: 1371 | D18: 31.75 | E18: 0 | F18: 0 | G18: 0 | H18: 31.75 | I18: 0 | J18: 31.75 | K18: 3.83
... A222: SURENDRAN SUBRAMANI | B222: WRHS | C222: 205 | D222: 29.75 | E222: 0 | F222: 7.75 | G222: 8 | H222: 45.5 | I222: 0 | J222: 45.5 | K222: 5.49
A224: Adjustments (0)
A225: Manual hour corrections recorded in the legacy weekly file.
B226: Name | C226: Type | D226: Value
A228: Category totals
A229: Sum of hours by work category for this week (SUMIFS from employee rows above).
B230: Category | D230: Basic hours | E230: Mon–Fri overtime | F230: Sat/Sun overtime | G230: Annual holiday | H230: Total paid hours
B231: A-EL CLNR | D231: =SUMIFS($D$7:$D$222,$B$7:$B$222,$B231) | E231: =SUMIFS($E$7:$E$222,$B$7:$B$222,$B231) | F231: =SUMIFS($F$7:$F$222,$B$7:$B$222,$B231) | G231: =SUMIFS($G$7:$G$222,$B$7:$B$222,$B231) | H231: =SUMIFS($H$7:$H$222,$B$7:$B$222,$B231)
B232: A-EL DPCH | D232: =SUMIFS($D$7:$D$222,$B$7:$B$222,$B232) | E232: =SUMIFS($E$7:$E$222,$B$7:$B$222,$B232) | F232: =SUMIFS($F$7:$F$222,$B$7:$B$222,$B232) | G232: =SUMIFS($G$7:$G$222,$B$7:$B$222,$B232) | H232: =SUMIFS($H$7:$H$222,$B$7:$B$222,$B232)
B233: A-EL OFCE | D233: =SUMIFS($D$7:$D$222,$B$7:$B$222,$B233) | E233: =SUMIFS($E$7:$E$222,$B$7:$B$222,$B233) | F233: =SUMIFS($F$7:$F$222,$B$7:$B$222,$B233) | G233: =SUMIFS($G$7:$G$222,$B$7:$B$222,$B233) | H233: =SUMIFS($H$7:$H$222,$B$7:$B$222,$B233)
B234: A-EL PKNG HIGH_RISK | D234: =SUMIFS($D$7:$D$222,$B$7:$B$222,$B234) | E234: =SUMIFS($E$7:$E$222,$B$7:$B$222,$B234) | F234: =SUMIFS($F$7:$F$222,$B$7:$B$222,$B234) | G234: =SUMIFS($G$7:$G$222,$B$7:$B$222,$B234) | H234: =SUMIFS($H$7:$H$222,$B$7:$B$222,$B234)
B235: A-EL PKNG SLEEVING | D235: =SUMIFS($D$7:$D$222,$B$7:$B$222,$B235) | E235: =SUMIFS($E$7:$E$222,$B$7:$B$222,$B235) | F235: =SUMIFS($F$7:$F$222,$B$7:$B$222,$B235) | G235: =SUMIFS($G$7:$G$222,$B$7:$B$222,$B235) | H235: =SUMIFS($H$7:$H$222,$B$7:$B$222,$B235)
B236: A-EL PROD BELT | D236: =SUMIFS($D$7:$D$222,$B$7:$B$222,$B236) | E236: =SUMIFS($E$7:$E$222,$B$7:$B$222,$B236) | F236: =SUMIFS($F$7:$F$222,$B$7:$B$222,$B236) | G236: =SUMIFS($G$7:$G$222,$B$7:$B$222,$B236) | H236: =SUMIFS($H$7:$H$222,$B$7:$B$222,$B236)
B237: A-EL PROD FORMING | D237: =SUMIFS($D$7:$D$222,$B$7:$B$222,$B237) | E237: =SUMIFS($E$7:$E$222,$B$7:$B$222,$B237) | F237: =SUMIFS($F$7:$F$222,$B$7:$B$222,$B237) | G237: =SUMIFS($G$7:$G$222,$B$7:$B$222,$B237) | H237: =SUMIFS($H$7:$H$222,$B$7:$B$222,$B237)
B238: A-EL PROD FRYING | D238: =SUMIFS($D$7:$D$222,$B$7:$B$222,$B238) | E238: =SUMIFS($E$7:$E$222,$B$7:$B$222,$B238) | F238: =SUMIFS($F$7:$F$222,$B$7:$B$222,$B238) | G238: =SUMIFS($G$7:$G$222,$B$7:$B$222,$B238) | H238: =SUMIFS($H$7:$H$222,$B$7:$B$222,$B238)
B239: A-EL PROD PREPARATION | D239: =SUMIFS($D$7:$D$222,$B$7:$B$222,$B239) | E239: =SUMIFS($E$7:$E$222,$B$7:$B$222,$B239) | F239: =SUMIFS($F$7:$F$222,$B$7:$B$222,$B239) | G239: =SUMIFS($G$7:$G$222,$B$7:$B$222,$B239) | H239: =SUMIFS($H$7:$H$222,$B$7:$B$222,$B239)
B240: A-EL TECHNICAL | D240: =SUMIFS($D$7:$D$222,$B$7:$B$222,$B240) | E240: =SUMIFS($E$7:$E$222,$B$7:$B$222,$B240) | F240: =SUMIFS($F$7:$F$222,$B$7:$B$222,$B240) | G240: =SUMIFS($G$7:$G$222,$B$7:$B$222,$B240) | H240: =SUMIFS($H$7:$H$222,$B$7:$B$222,$B240)
B241: A-EL WRHS | D241: =SUMIFS($D$7:$D$222,$B$7:$B$222,$B241) | E241: =SUMIFS($E$7:$E$222,$B$7:$B$222,$B241) | F241: =SUMIFS($F$7:$F$222,$B$7:$B$222,$B241) | G241: =SUMIFS($G$7:$G$222,$B$7:$B$222,$B241) | H241: =SUMIFS($H$7:$H$222,$B$7:$B$222,$B241)
B242: A-PM PKNG HIGH_RISK | D242: =SUMIFS($D$7:$D$222,$B$7:$B$222,$B242) | E242: =SUMIFS($E$7:$E$222,$B$7:$B$222,$B242) | F242: =SUMIFS($F$7:$F$222,$B$7:$B$222,$B242) | G242: =SUMIFS($G$7:$G$222,$B$7:$B$222,$B242) | H242: =SUMIFS($H$7:$H$222,$B$7:$B$222,$B242)
... B257: WRHS | D257: =SUMIFS($D$7:$D$222,$B$7:$B$222,$B257) | E257: =SUMIFS($E$7:$E$222,$B$7:$B$222,$B257) | F257: =SUMIFS($F$7:$F$222,$B$7:$B$222,$B257) | G257: =SUMIFS($G$7:$G$222,$B$7:$B$222,$B257) | H257: =SUMIFS($H$7:$H$222,$B$7:$B$222,$B257)
A259: Grouped totals (by category prefix)
A260: Categories rolled up to 4-character groups.
B261: Category | D261: Basic hours | E261: Mon–Fri overtime | F261: Sat/Sun overtime | G261: Annual holiday | H261: Total paid hours
B262: A-EL CLNR | D262: 186 | E262: 14.25 | F262: 0 | G262: 0 | H262: 200.25
...

Sheet Week3
A1: Gazebo HR — Week 3
A4: Week 3 — Employee paid hours
A5: One row per employee for this pay week (from weekly export).
A6: Name | B6: Category | C6: Pay ID (Sage) | D6: Basic hours | E6: Mon–Fri overtime | F6: Sat/Sun overtime | G6: Annual holiday | H6: Total paid hours | I6: Contracted hours | J6: Extra hours | K6: Additional holiday pay
A7: RAMJI BABU EOLL | B7: A-EL CLNR | C7: 1564 | D7: 35.25 | E7: 0 | F7: 0 | G7: 0 | H7: 35.25 | I7: 0 | J7: 35.25 | K7: 4.25
A8: KANJI BAGOANE EOLL | B8: A-EL CLNR | C8: 1683 | D8: 0 | E8: 0 | F8: 0 | G8: 0 | H8: 0 | I8: 0 | J8: 0 | K8: 0
A9: VELJI BAGUANE EOLL | B9: A-EL CLNR | C9: 1681 | D9: 0 | E9: 0 | F9: 0 | G9: 0 | H9: 0 | I9: 0 | J9: 0 | K9: 0
A10: DIPEN BAMANIA EOLL | B10: A-EL CLNR | C10: 1635 | D10: 32.5 | E10: 8.25 | F10: 0 | G10: 0 | H10: 40.75 | I10: 0 | J10: 40.75 | K10: 4.92
A11: SAVJI CHAGANA EOLL | B11: A-EL CLNR | C11: 1659 | D11: 31.75 | E11: 0 | F11: 0 | G11: 0 | H11: 31.75 | I11: 0 | J11: 31.75 | K11: 3.83
A12: KIRANKUMAR CHAUDHARY EOLL | B12: A-EL CLNR | C12: 1685 | D12: 0 | E12: 0 | F12: 0 | G12: 0 | H12: 0 | I12: 0 | J12: 0 | K12: 0
A13: HALPATI DHIRAJ RAMAN EOLL | B13: A-EL CLNR | C13: 1670 | D13: 35.25 | E13: 0 | F13: 0 | G13: 0 | H13: 35.25 | I13: 0 | J13: 35.25 | K13: 4.25
A14: MANN HASMUKHBHAI VIRANI EOLL | B14: A-EL CLNR | C14: 1684 | D14: 0 | E14: 0 | F14: 0 | G14: 0 | H14: 0 | I14: 0 | J14: 0 | K14: 0
A15: KAMLESH NATVAR EOLL | B15: A-EL CLNR | C15: 1563 | D15: 39.5 | E15: 0 | F15: 0 | G15: 0 | H15: 39.5 | I15: 0 | J15: 39.5 | K15: 4.77
A16: LALJI SOMA EOLL | B16: A-EL CLNR | C16: 1262 | D16: 25.25 | E16: 7 | F16: 0 | G16: 0 | H16: 32.25 | I16: 0 | J16: 32.25 | K16: 3.89
A17: DHANJI VIRA EOLL | B17: A-EL CLNR | C17: 1634 | D17: 0 | E17: 0 | F17: 0 | G17: 0 | H17: 0 | I17: 0 | J17: 0 | K17: 0
A18: AJAYKUMAR VIRA EOLL | B18: A-EL DPCH | C18: 1371 | D18: 7.5 | E18: 0 | F18: 0 | G18: 0 | H18: 7.5 | I18: 0 | J18: 7.5 | K18: 0.91
... A222: SURENDRAN SUBRAMANI | B222: WRHS | C222: 205 | D222: 30 | E222: 0 | F222: 7.75 | G222: 0 | H222: 37.75 | I222: 0 | J222: 37.75 | K222: 4.56
A224: Adjustments (0)
A225: Manual hour corrections recorded in the legacy weekly file.
B226: Name | C226: Type | D226: Value
A228: Category totals
A229: Sum of hours by work category for this week (SUMIFS from employee rows above).
B230: Category | D230: Basic hours | E230: Mon–Fri overtime | F230: Sat/Sun overtime | G230: Annual holiday | H230: Total paid hours
B231: A-EL CLNR | D231: =SUMIFS($D$7:$D$222,$B$7:$B$222,$B231) | E231: =SUMIFS($E$7:$E$222,$B$7:$B$222,$B231) | F231: =SUMIFS($F$7:$F$222,$B$7:$B$222,$B231) | G231: =SUMIFS($G$7:$G$222,$B$7:$B$222,$B231) | H231: =SUMIFS($H$7:$H$222,$B$7:$B$222,$B231)
B232: A-EL DPCH | D232: =SUMIFS($D$7:$D$222,$B$7:$B$222,$B232) | E232: =SUMIFS($E$7:$E$222,$B$7:$B$222,$B232) | F232: =SUMIFS($F$7:$F$222,$B$7:$B$222,$B232) | G232: =SUMIFS($G$7:$G$222,$B$7:$B$222,$B232) | H232: =SUMIFS($H$7:$H$222,$B$7:$B$222,$B232)
B233: A-EL OFCE | D233: =SUMIFS($D$7:$D$222,$B$7:$B$222,$B233) | E233: =SUMIFS($E$7:$E$222,$B$7:$B$222,$B233) | F233: =SUMIFS($F$7:$F$222,$B$7:$B$222,$B233) | G233: =SUMIFS($G$7:$G$222,$B$7:$B$222,$B233) | H233: =SUMIFS($H$7:$H$222,$B$7:$B$222,$B233)
B234: A-EL PKNG HIGH_RISK | D234: =SUMIFS($D$7:$D$222,$B$7:$B$222,$B234) | E234: =SUMIFS($E$7:$E$222,$B$7:$B$222,$B234) | F234: =SUMIFS($F$7:$F$222,$B$7:$B$222,$B234) | G234: =SUMIFS($G$7:$G$222,$B$7:$B$222,$B234) | H234: =SUMIFS($H$7:$H$222,$B$7:$B$222,$B234)
B235: A-EL PKNG SLEEVING | D235: =SUMIFS($D$7:$D$222,$B$7:$B$222,$B235) | E235: =SUMIFS($E$7:$E$222,$B$7:$B$222,$B235) | F235: =SUMIFS($F$7:$F$222,$B$7:$B$222,$B235) | G235: =SUMIFS($G$7:$G$222,$B$7:$B$222,$B235) | H235: =SUMIFS($H$7:$H$222,$B$7:$B$222,$B235)
B236: A-EL PROD BELT | D236: =SUMIFS($D$7:$D$222,$B$7:$B$222,$B236) | E236: =SUMIFS($E$7:$E$222,$B$7:$B$222,$B236) | F236: =SUMIFS($F$7:$F$222,$B$7:$B$222,$B236) | G236: =SUMIFS($G$7:$G$222,$B$7:$B$222,$B236) | H236: =SUMIFS($H$7:$H$222,$B$7:$B$222,$B236)
B237: A-EL PROD FORMING | D237: =SUMIFS($D$7:$D$222,$B$7:$B$222,$B237) | E237: =SUMIFS($E$7:$E$222,$B$7:$B$222,$B237) | F237: =SUMIFS($F$7:$F$222,$B$7:$B$222,$B237) | G237: =SUMIFS($G$7:$G$222,$B$7:$B$222,$B237) | H237: =SUMIFS($H$7:$H$222,$B$7:$B$222,$B237)
B238: A-EL PROD FRYING | D238: =SUMIFS($D$7:$D$222,$B$7:$B$222,$B238) | E238: =SUMIFS($E$7:$E$222,$B$7:$B$222,$B238) | F238: =SUMIFS($F$7:$F$222,$B$7:$B$222,$B238) | G238: =SUMIFS($G$7:$G$222,$B$7:$B$222,$B238) | H238: =SUMIFS($H$7:$H$222,$B$7:$B$222,$B238)
B239: A-EL PROD PREPARATION | D239: =SUMIFS($D$7:$D$222,$B$7:$B$222,$B239) | E239: =SUMIFS($E$7:$E$222,$B$7:$B$222,$B239) | F239: =SUMIFS($F$7:$F$222,$B$7:$B$222,$B239) | G239: =SUMIFS($G$7:$G$222,$B$7:$B$222,$B239) | H239: =SUMIFS($H$7:$H$222,$B$7:$B$222,$B239)
B240: A-EL TECHNICAL | D240: =SUMIFS($D$7:$D$222,$B$7:$B$222,$B240) | E240: =SUMIFS($E$7:$E$222,$B$7:$B$222,$B240) | F240: =SUMIFS($F$7:$F$222,$B$7:$B$222,$B240) | G240: =SUMIFS($G$7:$G$222,$B$7:$B$222,$B240) | H240: =SUMIFS($H$7:$H$222,$B$7:$B$222,$B240)
B241: A-EL WRHS | D241: =SUMIFS($D$7:$D$222,$B$7:$B$222,$B241) | E241: =SUMIFS($E$7:$E$222,$B$7:$B$222,$B241) | F241: =SUMIFS($F$7:$F$222,$B$7:$B$222,$B241) | G241: =SUMIFS($G$7:$G$222,$B$7:$B$222,$B241) | H241: =SUMIFS($H$7:$H$222,$B$7:$B$222,$B241)
B242: A-PM PKNG HIGH_RISK | D242: =SUMIFS($D$7:$D$222,$B$7:$B$222,$B242) | E242: =SUMIFS($E$7:$E$222,$B$7:$B$222,$B242) | F242: =SUMIFS($F$7:$F$222,$B$7:$B$222,$B242) | G242: =SUMIFS($G$7:$G$222,$B$7:$B$222,$B242) | H242: =SUMIFS($H$7:$H$222,$B$7:$B$222,$B242)
... B257: WRHS | D257: =SUMIFS($D$7:$D$222,$B$7:$B$222,$B257) | E257: =SUMIFS($E$7:$E$222,$B$7:$B$222,$B257) | F257: =SUMIFS($F$7:$F$222,$B$7:$B$222,$B257) | G257: =SUMIFS($G$7:$G$222,$B$7:$B$222,$B257) | H257: =SUMIFS($H$7:$H$222,$B$7:$B$222,$B257)
A259: Grouped totals (by category prefix)
A260: Categories rolled up to 4-character groups.
B261: Category | D261: Basic hours | E261: Mon–Fri overtime | F261: Sat/Sun overtime | G261: Annual holiday | H261: Total paid hours
B262: A-EL CLNR | D262: 199.5 | E262: 15.25 | F262: 0 | G262: 0 | H262: 214.75
...

Sheet Week4
A1: Gazebo HR — Week 4
A4: Week 4 — Employee paid hours
A5: One row per employee for this pay week (from weekly export).
A6: Name | B6: Category | C6: Pay ID (Sage) | D6: Basic hours | E6: Mon–Fri overtime | F6: Sat/Sun overtime | G6: Annual holiday | H6: Total paid hours | I6: Contracted hours | J6: Extra hours | K6: Additional holiday pay
A7: RAMJI BABU EOLL | B7: A-EL CLNR | C7: 1564 | D7: 41 | E7: 0 | F7: 0 | G7: 0 | H7: 41 | I7: 0 | J7: 41 | K7: 4.95
A8: KANJI BAGOANE EOLL | B8: A-EL CLNR | C8: 1683 | D8: 0 | E8: 0 | F8: 0 | G8: 0 | H8: 0 | I8: 0 | J8: 0 | K8: 0
A9: VELJI BAGUANE EOLL | B9: A-EL CLNR | C9: 1681 | D9: 0 | E9: 0 | F9: 0 | G9: 0 | H9: 0 | I9: 0 | J9: 0 | K9: 0
A10: DIPEN BAMANIA EOLL | B10: A-EL CLNR | C10: 1635 | D10: 32.75 | E10: 0 | F10: 4.5 | G10: 0 | H10: 37.25 | I10: 0 | J10: 37.25 | K10: 4.5
A11: SAVJI CHAGANA EOLL | B11: A-EL CLNR | C11: 1659 | D11: 41.25 | E11: 9.5 | F11: 0 | G11: 0 | H11: 50.75 | I11: 0 | J11: 50.75 | K11: 6.13
A12: KIRANKUMAR CHAUDHARY EOLL | B12: A-EL CLNR | C12: 1685 | D12: 0 | E12: 0 | F12: 0 | G12: 0 | H12: 0 | I12: 0 | J12: 0 | K12: 0
A13: HALPATI DHIRAJ RAMAN EOLL | B13: A-EL CLNR | C13: 1670 | D13: 39.5 | E13: 0 | F13: 0 | G13: 0 | H13: 39.5 | I13: 0 | J13: 39.5 | K13: 4.77
A14: MANN HASMUKHBHAI VIRANI EOLL | B14: A-EL CLNR | C14: 1684 | D14: 0 | E14: 0 | F14: 0 | G14: 0 | H14: 0 | I14: 0 | J14: 0 | K14: 0
A15: KAMLESH NATVAR EOLL | B15: A-EL CLNR | C15: 1563 | D15: 34.25 | E15: 0 | F15: 5.25 | G15: 0 | H15: 39.5 | I15: 0 | J15: 39.5 | K15: 4.77
A16: LALJI SOMA EOLL | B16: A-EL CLNR | C16: 1262 | D16: 41 | E16: 0 | F16: 0 | G16: 0 | H16: 41 | I16: 0 | J16: 41 | K16: 4.95
A17: DHANJI VIRA EOLL | B17: A-EL CLNR | C17: 1634 | D17: 0 | E17: 0 | F17: 0 | G17: 0 | H17: 0 | I17: 0 | J17: 0 | K17: 0
A18: AJAYKUMAR VIRA EOLL | B18: A-EL DPCH | C18: 1371 | D18: 0 | E18: 0 | F18: 0 | G18: 0 | H18: 0 | I18: 0 | J18: 0 | K18: 0
... A222: SURENDRAN SUBRAMANI | B222: WRHS | C222: 205 | D222: 22.5 | E222: 0 | F222: 7.5 | G222: 0 | H222: 30 | I222: 0 | J222: 30 | K222: 3.62
A224: Adjustments (0)
A225: Manual hour corrections recorded in the legacy weekly file.
B226: Name | C226: Type | D226: Value
A228: Category totals
A229: Sum of hours by work category for this week (SUMIFS from employee rows above).
B230: Category | D230: Basic hours | E230: Mon–Fri overtime | F230: Sat/Sun overtime | G230: Annual holiday | H230: Total paid hours
B231: A-EL CLNR | D231: =SUMIFS($D$7:$D$222,$B$7:$B$222,$B231) | E231: =SUMIFS($E$7:$E$222,$B$7:$B$222,$B231) | F231: =SUMIFS($F$7:$F$222,$B$7:$B$222,$B231) | G231: =SUMIFS($G$7:$G$222,$B$7:$B$222,$B231) | H231: =SUMIFS($H$7:$H$222,$B$7:$B$222,$B231)
B232: A-EL DPCH | D232: =SUMIFS($D$7:$D$222,$B$7:$B$222,$B232) | E232: =SUMIFS($E$7:$E$222,$B$7:$B$222,$B232) | F232: =SUMIFS($F$7:$F$222,$B$7:$B$222,$B232) | G232: =SUMIFS($G$7:$G$222,$B$7:$B$222,$B232) | H232: =SUMIFS($H$7:$H$222,$B$7:$B$222,$B232)
B233: A-EL OFCE | D233: =SUMIFS($D$7:$D$222,$B$7:$B$222,$B233) | E233: =SUMIFS($E$7:$E$222,$B$7:$B$222,$B233) | F233: =SUMIFS($F$7:$F$222,$B$7:$B$222,$B233) | G233: =SUMIFS($G$7:$G$222,$B$7:$B$222,$B233) | H233: =SUMIFS($H$7:$H$222,$B$7:$B$222,$B233)
B234: A-EL PKNG HIGH_RISK | D234: =SUMIFS($D$7:$D$222,$B$7:$B$222,$B234) | E234: =SUMIFS($E$7:$E$222,$B$7:$B$222,$B234) | F234: =SUMIFS($F$7:$F$222,$B$7:$B$222,$B234) | G234: =SUMIFS($G$7:$G$222,$B$7:$B$222,$B234) | H234: =SUMIFS($H$7:$H$222,$B$7:$B$222,$B234)
B235: A-EL PKNG SLEEVING | D235: =SUMIFS($D$7:$D$222,$B$7:$B$222,$B235) | E235: =SUMIFS($E$7:$E$222,$B$7:$B$222,$B235) | F235: =SUMIFS($F$7:$F$222,$B$7:$B$222,$B235) | G235: =SUMIFS($G$7:$G$222,$B$7:$B$222,$B235) | H235: =SUMIFS($H$7:$H$222,$B$7:$B$222,$B235)
B236: A-EL PROD BELT | D236: =SUMIFS($D$7:$D$222,$B$7:$B$222,$B236) | E236: =SUMIFS($E$7:$E$222,$B$7:$B$222,$B236) | F236: =SUMIFS($F$7:$F$222,$B$7:$B$222,$B236) | G236: =SUMIFS($G$7:$G$222,$B$7:$B$222,$B236) | H236: =SUMIFS($H$7:$H$222,$B$7:$B$222,$B236)
B237: A-EL PROD FORMING | D237: =SUMIFS($D$7:$D$222,$B$7:$B$222,$B237) | E237: =SUMIFS($E$7:$E$222,$B$7:$B$222,$B237) | F237: =SUMIFS($F$7:$F$222,$B$7:$B$222,$B237) | G237: =SUMIFS($G$7:$G$222,$B$7:$B$222,$B237) | H237: =SUMIFS($H$7:$H$222,$B$7:$B$222,$B237)
B238: A-EL PROD FRYING | D238: =SUMIFS($D$7:$D$222,$B$7:$B$222,$B238) | E238: =SUMIFS($E$7:$E$222,$B$7:$B$222,$B238) | F238: =SUMIFS($F$7:$F$222,$B$7:$B$222,$B238) | G238: =SUMIFS($G$7:$G$222,$B$7:$B$222,$B238) | H238: =SUMIFS($H$7:$H$222,$B$7:$B$222,$B238)
B239: A-EL PROD PREPARATION | D239: =SUMIFS($D$7:$D$222,$B$7:$B$222,$B239) | E239: =SUMIFS($E$7:$E$222,$B$7:$B$222,$B239) | F239: =SUMIFS($F$7:$F$222,$B$7:$B$222,$B239) | G239: =SUMIFS($G$7:$G$222,$B$7:$B$222,$B239) | H239: =SUMIFS($H$7:$H$222,$B$7:$B$222,$B239)
B240: A-EL TECHNICAL | D240: =SUMIFS($D$7:$D$222,$B$7:$B$222,$B240) | E240: =SUMIFS($E$7:$E$222,$B$7:$B$222,$B240) | F240: =SUMIFS($F$7:$F$222,$B$7:$B$222,$B240) | G240: =SUMIFS($G$7:$G$222,$B$7:$B$222,$B240) | H240: =SUMIFS($H$7:$H$222,$B$7:$B$222,$B240)
B241: A-EL WRHS | D241: =SUMIFS($D$7:$D$222,$B$7:$B$222,$B241) | E241: =SUMIFS($E$7:$E$222,$B$7:$B$222,$B241) | F241: =SUMIFS($F$7:$F$222,$B$7:$B$222,$B241) | G241: =SUMIFS($G$7:$G$222,$B$7:$B$222,$B241) | H241: =SUMIFS($H$7:$H$222,$B$7:$B$222,$B241)
B242: A-PM PKNG HIGH_RISK | D242: =SUMIFS($D$7:$D$222,$B$7:$B$222,$B242) | E242: =SUMIFS($E$7:$E$222,$B$7:$B$222,$B242) | F242: =SUMIFS($F$7:$F$222,$B$7:$B$222,$B242) | G242: =SUMIFS($G$7:$G$222,$B$7:$B$222,$B242) | H242: =SUMIFS($H$7:$H$222,$B$7:$B$222,$B242)
... B257: WRHS | D257: =SUMIFS($D$7:$D$222,$B$7:$B$222,$B257) | E257: =SUMIFS($E$7:$E$222,$B$7:$B$222,$B257) | F257: =SUMIFS($F$7:$F$222,$B$7:$B$222,$B257) | G257: =SUMIFS($G$7:$G$222,$B$7:$B$222,$B257) | H257: =SUMIFS($H$7:$H$222,$B$7:$B$222,$B257)
A259: Grouped totals (by category prefix)
A260: Categories rolled up to 4-character groups.
B261: Category | D261: Basic hours | E261: Mon–Fri overtime | F261: Sat/Sun overtime | G261: Annual holiday | H261: Total paid hours
B262: A-EL CLNR | D262: 229.75 | E262: 9.5 | F262: 9.75 | G262: 0 | H262: 249
...

Sheet Summary
A1: Gazebo HR — Monthly Summary
A4: Monthly summary — all employees (weeks combined)
A5: Total paid hours per employee across all uploaded weeks. Totals use Excel formulas — click any hour cell to see Week sheet references.
A6: Name | B6: Category | C6: Pay ID (Sage) | D6: Basic hours | E6: Mon–Fri overtime | F6: Sat/Sun overtime | G6: Annual holiday | H6: Total paid hours | I6: Contracted hours | J6: Extra hours | K6: Additional holiday pay
A7: RAMJI BABU EOLL | B7: A-EL CLNR | C7: 1564 | D7: =SUMIF('Week1'!$A:$A,$A7,'Week1'!$D:$D)+SUMIF('Week2'!$A:$A,$A7,'Week2'!$D:$D)+SUMIF('Week3'!$A:$A,$A7,'Week3'!$D:$D)+SUMIF('Week4'!$A:$A,$A7,'Week4'!$D:$D) | E7: =SUMIF('Week1'!$A:$A,$A7,'Week1'!$E:$E)+SUMIF('Week2'!$A:$A,$A7,'Week2'!$E:$E)+SUMIF('Week3'!$A:$A,$A7,'Week3'!$E:$E)+SUMIF('Week4'!$A:$A,$A7,'Week4'!$E:$E) | F7: =SUMIF('Week1'!$A:$A,$A7,'Week1'!$F:$F)+SUMIF('Week2'!$A:$A,$A7,'Week2'!$F:$F)+SUMIF('Week3'!$A:$A,$A7,'Week3'!$F:$F)+SUMIF('Week4'!$A:$A,$A7,'Week4'!$F:$F) | G7: =SUMIF('Week1'!$A:$A,$A7,'Week1'!$G:$G)+SUMIF('Week2'!$A:$A,$A7,'Week2'!$G:$G)+SUMIF('Week3'!$A:$A,$A7,'Week3'!$G:$G)+SUMIF('Week4'!$A:$A,$A7,'Week4'!$G:$G) | H7: =SUMIF('Week1'!$A:$A,$A7,'Week1'!$H:$H)+SUMIF('Week2'!$A:$A,$A7,'Week2'!$H:$H)+SUMIF('Week3'!$A:$A,$A7,'Week3'!$H:$H)+SUMIF('Week4'!$A:$A,$A7,'Week4'!$H:$H) | I7: =SUMIF('Week1'!$A:$A,$A7,'Week1'!$I:$I)+SUMIF('Week2'!$A:$A,$A7,'Week2'!$I:$I)+SUMIF('Week3'!$A:$A,$A7,'Week3'!$I:$I)+SUMIF('Week4'!$A:$A,$A7,'Week4'!$I:$I) | J7: =SUMIF('Week1'!$A:$A,$A7,'Week1'!$J:$J)+SUMIF('Week2'!$A:$A,$A7,'Week2'!$J:$J)+SUMIF('Week3'!$A:$A,$A7,'Week3'!$J:$J)+SUMIF('Week4'!$A:$A,$A7,'Week4'!$J:$J) | K7: =SUMIF('Week1'!$A:$A,$A7,'Week1'!$K:$K)+SUMIF('Week2'!$A:$A,$A7,'Week2'!$K:$K)+SUMIF('Week3'!$A:$A,$A7,'Week3'!$K:$K)+SUMIF('Week4'!$A:$A,$A7,'Week4'!$K:$K)
A8: DIPEN BAMANIA EOLL | B8: A-EL CLNR | C8: 1635 | D8: =SUMIF('Week1'!$A:$A,$A8,'Week1'!$D:$D)+SUMIF('Week2'!$A:$A,$A8,'Week2'!$D:$D)+SUMIF('Week3'!$A:$A,$A8,'Week3'!$D:$D)+SUMIF('Week4'!$A:$A,$A8,'Week4'!$D:$D) | E8: =SUMIF('Week1'!$A:$A,$A8,'Week1'!$E:$E)+SUMIF('Week2'!$A:$A,$A8,'Week2'!$E:$E)+SUMIF('Week3'!$A:$A,$A8,'Week3'!$E:$E)+SUMIF('Week4'!$A:$A,$A8,'Week4'!$E:$E) | F8: =SUMIF('Week1'!$A:$A,$A8,'Week1'!$F:$F)+SUMIF('Week2'!$A:$A,$A8,'Week2'!$F:$F)+SUMIF('Week3'!$A:$A,$A8,'Week3'!$F:$F)+SUMIF('Week4'!$A:$A,$A8,'Week4'!$F:$F) | G8: =SUMIF('Week1'!$A:$A,$A8,'Week1'!$G:$G)+SUMIF('Week2'!$A:$A,$A8,'Week2'!$G:$G)+SUMIF('Week3'!$A:$A,$A8,'Week3'!$G:$G)+SUMIF('Week4'!$A:$A,$A8,'Week4'!$G:$G) | H8: =SUMIF('Week1'!$A:$A,$A8,'Week1'!$H:$H)+SUMIF('Week2'!$A:$A,$A8,'Week2'!$H:$H)+SUMIF('Week3'!$A:$A,$A8,'Week3'!$H:$H)+SUMIF('Week4'!$A:$A,$A8,'Week4'!$H:$H) | I8: =SUMIF('Week1'!$A:$A,$A8,'Week1'!$I:$I)+SUMIF('Week2'!$A:$A,$A8,'Week2'!$I:$I)+SUMIF('Week3'!$A:$A,$A8,'Week3'!$I:$I)+SUMIF('Week4'!$A:$A,$A8,'Week4'!$I:$I) | J8: =SUMIF('Week1'!$A:$A,$A8,'Week1'!$J:$J)+SUMIF('Week2'!$A:$A,$A8,'Week2'!$J:$J)+SUMIF('Week3'!$A:$A,$A8,'Week3'!$J:$J)+SUMIF('Week4'!$A:$A,$A8,'Week4'!$J:$J) | K8: =SUMIF('Week1'!$A:$A,$A8,'Week1'!$K:$K)+SUMIF('Week2'!$A:$A,$A8,'Week2'!$K:$K)+SUMIF('Week3'!$A:$A,$A8,'Week3'!$K:$K)+SUMIF('Week4'!$A:$A,$A8,'Week4'!$K:$K)
A9: SAVJI CHAGANA EOLL | B9: A-EL CLNR | C9: 1659 | D9: =SUMIF('Week1'!$A:$A,$A9,'Week1'!$D:$D)+SUMIF('Week2'!$A:$A,$A9,'Week2'!$D:$D)+SUMIF('Week3'!$A:$A,$A9,'Week3'!$D:$D)+SUMIF('Week4'!$A:$A,$A9,'Week4'!$D:$D) | E9: =SUMIF('Week1'!$A:$A,$A9,'Week1'!$E:$E)+SUMIF('Week2'!$A:$A,$A9,'Week2'!$E:$E)+SUMIF('Week3'!$A:$A,$A9,'Week3'!$E:$E)+SUMIF('Week4'!$A:$A,$A9,'Week4'!$E:$E) | F9: =SUMIF('Week1'!$A:$A,$A9,'Week1'!$F:$F)+SUMIF('Week2'!$A:$A,$A9,'Week2'!$F:$F)+SUMIF('Week3'!$A:$A,$A9,'Week3'!$F:$F)+SUMIF('Week4'!$A:$A,$A9,'Week4'!$F:$F) | G9: =SUMIF('Week1'!$A:$A,$A9,'Week1'!$G:$G)+SUMIF('Week2'!$A:$A,$A9,'Week2'!$G:$G)+SUMIF('Week3'!$A:$A,$A9,'Week3'!$G:$G)+SUMIF('Week4'!$A:$A,$A9,'Week4'!$G:$G) | H9: =SUMIF('Week1'!$A:$A,$A9,'Week1'!$H:$H)+SUMIF('Week2'!$A:$A,$A9,'Week2'!$H:$H)+SUMIF('Week3'!$A:$A,$A9,'Week3'!$H:$H)+SUMIF('Week4'!$A:$A,$A9,'Week4'!$H:$H) | I9: =SUMIF('Week1'!$A:$A,$A9,'Week1'!$I:$I)+SUMIF('Week2'!$A:$A,$A9,'Week2'!$I:$I)+SUMIF('Week3'!$A:$A,$A9,'Week3'!$I:$I)+SUMIF('Week4'!$A:$A,$A9,'Week4'!$I:$I) | J9: =SUMIF('Week1'!$A:$A,$A9,'Week1'!$J:$J)+SUMIF('Week2'!$A:$A,$A9,'Week2'!$J:$J)+SUMIF('Week3'!$A:$A,$A9,'Week3'!$J:$J)+SUMIF('Week4'!$A:$A,$A9,'Week4'!$J:$J) | K9: =SUMIF('Week1'!$A:$A,$A9,'Week1'!$K:$K)+SUMIF('Week2'!$A:$A,$A9,'Week2'!$K:$K)+SUMIF('Week3'!$A:$A,$A9,'Week3'!$K:$K)+SUMIF('Week4'!$A:$A,$A9,'Week4'!$K:$K)
A10: KAMLESH NATVAR EOLL | B10: A-EL CLNR | C10: 1563 | D10: =SUMIF('Week1'!$A:$A,$A10,'Week1'!$D:$D)+SUMIF('Week2'!$A:$A,$A10,'Week2'!$D:$D)+SUMIF('Week3'!$A:$A,$A10,'Week3'!$D:$D)+SUMIF('Week4'!$A:$A,$A10,'Week4'!$D:$D) | E10: =SUMIF('Week1'!$A:$A,$A10,'Week1'!$E:$E)+SUMIF('Week2'!$A:$A,$A10,'Week2'!$E:$E)+SUMIF('Week3'!$A:$A,$A10,'Week3'!$E:$E)+SUMIF('Week4'!$A:$A,$A10,'Week4'!$E:$E) | F10: =SUMIF('Week1'!$A:$A,$A10,'Week1'!$F:$F)+SUMIF('Week2'!$A:$A,$A10,'Week2'!$F:$F)+SUMIF('Week3'!$A:$A,$A10,'Week3'!$F:$F)+SUMIF('Week4'!$A:$A,$A10,'Week4'!$F:$F) | G10: =SUMIF('Week1'!$A:$A,$A10,'Week1'!$G:$G)+SUMIF('Week2'!$A:$A,$A10,'Week2'!$G:$G)+SUMIF('Week3'!$A:$A,$A10,'Week3'!$G:$G)+SUMIF('Week4'!$A:$A,$A10,'Week4'!$G:$G) | H10: =SUMIF('Week1'!$A:$A,$A10,'Week1'!$H:$H)+SUMIF('Week2'!$A:$A,$A10,'Week2'!$H:$H)+SUMIF('Week3'!$A:$A,$A10,'Week3'!$H:$H)+SUMIF('Week4'!$A:$A,$A10,'Week4'!$H:$H) | I10: =SUMIF('Week1'!$A:$A,$A10,'Week1'!$I:$I)+SUMIF('Week2'!$A:$A,$A10,'Week2'!$I:$I)+SUMIF('Week3'!$A:$A,$A10,'Week3'!$I:$I)+SUMIF('Week4'!$A:$A,$A10,'Week4'!$I:$I) | J10: =SUMIF('Week1'!$A:$A,$A10,'Week1'!$J:$J)+SUMIF('Week2'!$A:$A,$A10,'Week2'!$J:$J)+SUMIF('Week3'!$A:$A,$A10,'Week3'!$J:$J)+SUMIF('Week4'!$A:$A,$A10,'Week4'!$J:$J) | K10: =SUMIF('Week1'!$A:$A,$A10,'Week1'!$K:$K)+SUMIF('Week2'!$A:$A,$A10,'Week2'!$K:$K)+SUMIF('Week3'!$A:$A,$A10,'Week3'!$K:$K)+SUMIF('Week4'!$A:$A,$A10,'Week4'!$K:$K)
A11: LALJI SOMA EOLL | B11: A-EL CLNR | C11: 1262 | D11: =SUMIF('Week1'!$A:$A,$A11,'Week1'!$D:$D)+SUMIF('Week2'!$A:$A,$A11,'Week2'!$D:$D)+SUMIF('Week3'!$A:$A,$A11,'Week3'!$D:$D)+SUMIF('Week4'!$A:$A,$A11,'Week4'!$D:$D) | E11: =SUMIF('Week1'!$A:$A,$A11,'Week1'!$E:$E)+SUMIF('Week2'!$A:$A,$A11,'Week2'!$E:$E)+SUMIF('Week3'!$A:$A,$A11,'Week3'!$E:$E)+SUMIF('Week4'!$A:$A,$A11,'Week4'!$E:$E) | F11: =SUMIF('Week1'!$A:$A,$A11,'Week1'!$F:$F)+SUMIF('Week2'!$A:$A,$A11,'Week2'!$F:$F)+SUMIF('Week3'!$A:$A,$A11,'Week3'!$F:$F)+SUMIF('Week4'!$A:$A,$A11,'Week4'!$F:$F) | G11: =SUMIF('Week1'!$A:$A,$A11,'Week1'!$G:$G)+SUMIF('Week2'!$A:$A,$A11,'Week2'!$G:$G)+SUMIF('Week3'!$A:$A,$A11,'Week3'!$G:$G)+SUMIF('Week4'!$A:$A,$A11,'Week4'!$G:$G) | H11: =SUMIF('Week1'!$A:$A,$A11,'Week1'!$H:$H)+SUMIF('Week2'!$A:$A,$A11,'Week2'!$H:$H)+SUMIF('Week3'!$A:$A,$A11,'Week3'!$H:$H)+SUMIF('Week4'!$A:$A,$A11,'Week4'!$H:$H) | I11: =SUMIF('Week1'!$A:$A,$A11,'Week1'!$I:$I)+SUMIF('Week2'!$A:$A,$A11,'Week2'!$I:$I)+SUMIF('Week3'!$A:$A,$A11,'Week3'!$I:$I)+SUMIF('Week4'!$A:$A,$A11,'Week4'!$I:$I) | J11: =SUMIF('Week1'!$A:$A,$A11,'Week1'!$J:$J)+SUMIF('Week2'!$A:$A,$A11,'Week2'!$J:$J)+SUMIF('Week3'!$A:$A,$A11,'Week3'!$J:$J)+SUMIF('Week4'!$A:$A,$A11,'Week4'!$J:$J) | K11: =SUMIF('Week1'!$A:$A,$A11,'Week1'!$K:$K)+SUMIF('Week2'!$A:$A,$A11,'Week2'!$K:$K)+SUMIF('Week3'!$A:$A,$A11,'Week3'!$K:$K)+SUMIF('Week4'!$A:$A,$A11,'Week4'!$K:$K)
A12: DHANJI VIRA EOLL | B12: A-EL CLNR | C12: 1634 | D12: =SUMIF('Week1'!$A:$A,$A12,'Week1'!$D:$D)+SUMIF('Week2'!$A:$A,$A12,'Week2'!$D:$D)+SUMIF('Week3'!$A:$A,$A12,'Week3'!$D:$D)+SUMIF('Week4'!$A:$A,$A12,'Week4'!$D:$D) | E12: =SUMIF('Week1'!$A:$A,$A12,'Week1'!$E:$E)+SUMIF('Week2'!$A:$A,$A12,'Week2'!$E:$E)+SUMIF('Week3'!$A:$A,$A12,'Week3'!$E:$E)+SUMIF('Week4'!$A:$A,$A12,'Week4'!$E:$E) | F12: =SUMIF('Week1'!$A:$A,$A12,'Week1'!$F:$F)+SUMIF('Week2'!$A:$A,$A12,'Week2'!$F:$F)+SUMIF('Week3'!$A:$A,$A12,'Week3'!$F:$F)+SUMIF('Week4'!$A:$A,$A12,'Week4'!$F:$F) | G12: =SUMIF('Week1'!$A:$A,$A12,'Week1'!$G:$G)+SUMIF('Week2'!$A:$A,$A12,'Week2'!$G:$G)+SUMIF('Week3'!$A:$A,$A12,'Week3'!$G:$G)+SUMIF('Week4'!$A:$A,$A12,'Week4'!$G:$G) | H12: =SUMIF('Week1'!$A:$A,$A12,'Week1'!$H:$H)+SUMIF('Week2'!$A:$A,$A12,'Week2'!$H:$H)+SUMIF('Week3'!$A:$A,$A12,'Week3'!$H:$H)+SUMIF('Week4'!$A:$A,$A12,'Week4'!$H:$H) | I12: =SUMIF('Week1'!$A:$A,$A12,'Week1'!$I:$I)+SUMIF('Week2'!$A:$A,$A12,'Week2'!$I:$I)+SUMIF('Week3'!$A:$A,$A12,'Week3'!$I:$I)+SUMIF('Week4'!$A:$A,$A12,'Week4'!$I:$I) | J12: =SUMIF('Week1'!$A:$A,$A12,'Week1'!$J:$J)+SUMIF('Week2'!$A:$A,$A12,'Week2'!$J:$J)+SUMIF('Week3'!$A:$A,$A12,'Week3'!$J:$J)+SUMIF('Week4'!$A:$A,$A12,'Week4'!$J:$J) | K12: =SUMIF('Week1'!$A:$A,$A12,'Week1'!$K:$K)+SUMIF('Week2'!$A:$A,$A12,'Week2'!$K:$K)+SUMIF('Week3'!$A:$A,$A12,'Week3'!$K:$K)+SUMIF('Week4'!$A:$A,$A12,'Week4'!$K:$K)
A13: AJAYKUMAR VIRA EOLL | B13: A-EL DPCH | C13: 1371 | D13: =SUMIF('Week1'!$A:$A,$A13,'Week1'!$D:$D)+SUMIF('Week2'!$A:$A,$A13,'Week2'!$D:$D)+SUMIF('Week3'!$A:$A,$A13,'Week3'!$D:$D)+SUMIF('Week4'!$A:$A,$A13,'Week4'!$D:$D) | E13: =SUMIF('Week1'!$A:$A,$A13,'Week1'!$E:$E)+SUMIF('Week2'!$A:$A,$A13,'Week2'!$E:$E)+SUMIF('Week3'!$A:$A,$A13,'Week3'!$E:$E)+SUMIF('Week4'!$A:$A,$A13,'Week4'!$E:$E) | F13: =SUMIF('Week1'!$A:$A,$A13,'Week1'!$F:$F)+SUMIF('Week2'!$A:$A,$A13,'Week2'!$F:$F)+SUMIF('Week3'!$A:$A,$A13,'Week3'!$F:$F)+SUMIF('Week4'!$A:$A,$A13,'Week4'!$F:$F) | G13: =SUMIF('Week1'!$A:$A,$A13,'Week1'!$G:$G)+SUMIF('Week2'!$A:$A,$A13,'Week2'!$G:$G)+SUMIF('Week3'!$A:$A,$A13,'Week3'!$G:$G)+SUMIF('Week4'!$A:$A,$A13,'Week4'!$G:$G) | H13: =SUMIF('Week1'!$A:$A,$A13,'Week1'!$H:$H)+SUMIF('Week2'!$A:$A,$A13,'Week2'!$H:$H)+SUMIF('Week3'!$A:$A,$A13,'Week3'!$H:$H)+SUMIF('Week4'!$A:$A,$A13,'Week4'!$H:$H) | I13: =SUMIF('Week1'!$A:$A,$A13,'Week1'!$I:$I)+SUMIF('Week2'!$A:$A,$A13,'Week2'!$I:$I)+SUMIF('Week3'!$A:$A,$A13,'Week3'!$I:$I)+SUMIF('Week4'!$A:$A,$A13,'Week4'!$I:$I) | J13: =SUMIF('Week1'!$A:$A,$A13,'Week1'!$J:$J)+SUMIF('Week2'!$A:$A,$A13,'Week2'!$J:$J)+SUMIF('Week3'!$A:$A,$A13,'Week3'!$J:$J)+SUMIF('Week4'!$A:$A,$A13,'Week4'!$J:$J) | K13: =SUMIF('Week1'!$A:$A,$A13,'Week1'!$K:$K)+SUMIF('Week2'!$A:$A,$A13,'Week2'!$K:$K)+SUMIF('Week3'!$A:$A,$A13,'Week3'!$K:$K)+SUMIF('Week4'!$A:$A,$A13,'Week4'!$K:$K)
A14: MEGHNABEN GANDHI EOLL | B14: A-EL OFCE | C14: 1668 | D14: =SUMIF('Week1'!$A:$A,$A14,'Week1'!$D:$D)+SUMIF('Week2'!$A:$A,$A14,'Week2'!$D:$D)+SUMIF('Week3'!$A:$A,$A14,'Week3'!$D:$D)+SUMIF('Week4'!$A:$A,$A14,'Week4'!$D:$D) | E14: =SUMIF('Week1'!$A:$A,$A14,'Week1'!$E:$E)+SUMIF('Week2'!$A:$A,$A14,'Week2'!$E:$E)+SUMIF('Week3'!$A:$A,$A14,'Week3'!$E:$E)+SUMIF('Week4'!$A:$A,$A14,'Week4'!$E:$E) | F14: =SUMIF('Week1'!$A:$A,$A14,'Week1'!$F:$F)+SUMIF('Week2'!$A:$A,$A14,'Week2'!$F:$F)+SUMIF('Week3'!$A:$A,$A14,'Week3'!$F:$F)+SUMIF('Week4'!$A:$A,$A14,'Week4'!$F:$F) | G14: =SUMIF('Week1'!$A:$A,$A14,'Week1'!$G:$G)+SUMIF('Week2'!$A:$A,$A14,'Week2'!$G:$G)+SUMIF('Week3'!$A:$A,$A14,'Week3'!$G:$G)+SUMIF('Week4'!$A:$A,$A14,'Week4'!$G:$G) | H14: =SUMIF('Week1'!$A:$A,$A14,'Week1'!$H:$H)+SUMIF('Week2'!$A:$A,$A14,'Week2'!$H:$H)+SUMIF('Week3'!$A:$A,$A14,'Week3'!$H:$H)+SUMIF('Week4'!$A:$A,$A14,'Week4'!$H:$H) | I14: =SUMIF('Week1'!$A:$A,$A14,'Week1'!$I:$I)+SUMIF('Week2'!$A:$A,$A14,'Week2'!$I:$I)+SUMIF('Week3'!$A:$A,$A14,'Week3'!$I:$I)+SUMIF('Week4'!$A:$A,$A14,'Week4'!$I:$I) | J14: =SUMIF('Week1'!$A:$A,$A14,'Week1'!$J:$J)+SUMIF('Week2'!$A:$A,$A14,'Week2'!$J:$J)+SUMIF('Week3'!$A:$A,$A14,'Week3'!$J:$J)+SUMIF('Week4'!$A:$A,$A14,'Week4'!$J:$J) | K14: =SUMIF('Week1'!$A:$A,$A14,'Week1'!$K:$K)+SUMIF('Week2'!$A:$A,$A14,'Week2'!$K:$K)+SUMIF('Week3'!$A:$A,$A14,'Week3'!$K:$K)+SUMIF('Week4'!$A:$A,$A14,'Week4'!$K:$K)
A15: KRISHKUMAR BHALALA EOLL | B15: A-EL PKNG HIGH_RISK | C15: 1540 | D15: =SUMIF('Week1'!$A:$A,$A15,'Week1'!$D:$D)+SUMIF('Week2'!$A:$A,$A15,'Week2'!$D:$D)+SUMIF('Week3'!$A:$A,$A15,'Week3'!$D:$D)+SUMIF('Week4'!$A:$A,$A15,'Week4'!$D:$D) | E15: =SUMIF('Week1'!$A:$A,$A15,'Week1'!$E:$E)+SUMIF('Week2'!$A:$A,$A15,'Week2'!$E:$E)+SUMIF('Week3'!$A:$A,$A15,'Week3'!$E:$E)+SUMIF('Week4'!$A:$A,$A15,'Week4'!$E:$E) | F15: =SUMIF('Week1'!$A:$A,$A15,'Week1'!$F:$F)+SUMIF('Week2'!$A:$A,$A15,'Week2'!$F:$F)+SUMIF('Week3'!$A:$A,$A15,'Week3'!$F:$F)+SUMIF('Week4'!$A:$A,$A15,'Week4'!$F:$F) | G15: =SUMIF('Week1'!$A:$A,$A15,'Week1'!$G:$G)+SUMIF('Week2'!$A:$A,$A15,'Week2'!$G:$G)+SUMIF('Week3'!$A:$A,$A15,'Week3'!$G:$G)+SUMIF('Week4'!$A:$A,$A15,'Week4'!$G:$G) | H15: =SUMIF('Week1'!$A:$A,$A15,'Week1'!$H:$H)+SUMIF('Week2'!$A:$A,$A15,'Week2'!$H:$H)+SUMIF('Week3'!$A:$A,$A15,'Week3'!$H:$H)+SUMIF('Week4'!$A:$A,$A15,'Week4'!$H:$H) | I15: =SUMIF('Week1'!$A:$A,$A15,'Week1'!$I:$I)+SUMIF('Week2'!$A:$A,$A15,'Week2'!$I:$I)+SUMIF('Week3'!$A:$A,$A15,'Week3'!$I:$I)+SUMIF('Week4'!$A:$A,$A15,'Week4'!$I:$I) | J15: =SUMIF('Week1'!$A:$A,$A15,'Week1'!$J:$J)+SUMIF('Week2'!$A:$A,$A15,'Week2'!$J:$J)+SUMIF('Week3'!$A:$A,$A15,'Week3'!$J:$J)+SUMIF('Week4'!$A:$A,$A15,'Week4'!$J:$J) | K15: =SUMIF('Week1'!$A:$A,$A15,'Week1'!$K:$K)+SUMIF('Week2'!$A:$A,$A15,'Week2'!$K:$K)+SUMIF('Week3'!$A:$A,$A15,'Week3'!$K:$K)+SUMIF('Week4'!$A:$A,$A15,'Week4'!$K:$K)
A16: SHRUTI BIPINBHAI DOBARIYA EOLL | B16: A-EL PKNG HIGH_RISK | C16: 1640 | D16: =SUMIF('Week1'!$A:$A,$A16,'Week1'!$D:$D)+SUMIF('Week2'!$A:$A,$A16,'Week2'!$D:$D)+SUMIF('Week3'!$A:$A,$A16,'Week3'!$D:$D)+SUMIF('Week4'!$A:$A,$A16,'Week4'!$D:$D) | E16: =SUMIF('Week1'!$A:$A,$A16,'Week1'!$E:$E)+SUMIF('Week2'!$A:$A,$A16,'Week2'!$E:$E)+SUMIF('Week3'!$A:$A,$A16,'Week3'!$E:$E)+SUMIF('Week4'!$A:$A,$A16,'Week4'!$E:$E) | F16: =SUMIF('Week1'!$A:$A,$A16,'Week1'!$F:$F)+SUMIF('Week2'!$A:$A,$A16,'Week2'!$F:$F)+SUMIF('Week3'!$A:$A,$A16,'Week3'!$F:$F)+SUMIF('Week4'!$A:$A,$A16,'Week4'!$F:$F) | G16: =SUMIF('Week1'!$A:$A,$A16,'Week1'!$G:$G)+SUMIF('Week2'!$A:$A,$A16,'Week2'!$G:$G)+SUMIF('Week3'!$A:$A,$A16,'Week3'!$G:$G)+SUMIF('Week4'!$A:$A,$A16,'Week4'!$G:$G) | H16: =SUMIF('Week1'!$A:$A,$A16,'Week1'!$H:$H)+SUMIF('Week2'!$A:$A,$A16,'Week2'!$H:$H)+SUMIF('Week3'!$A:$A,$A16,'Week3'!$H:$H)+SUMIF('Week4'!$A:$A,$A16,'Week4'!$H:$H) | I16: =SUMIF('Week1'!$A:$A,$A16,'Week1'!$I:$I)+SUMIF('Week2'!$A:$A,$A16,'Week2'!$I:$I)+SUMIF('Week3'!$A:$A,$A16,'Week3'!$I:$I)+SUMIF('Week4'!$A:$A,$A16,'Week4'!$I:$I) | J16: =SUMIF('Week1'!$A:$A,$A16,'Week1'!$J:$J)+SUMIF('Week2'!$A:$A,$A16,'Week2'!$J:$J)+SUMIF('Week3'!$A:$A,$A16,'Week3'!$J:$J)+SUMIF('Week4'!$A:$A,$A16,'Week4'!$J:$J) | K16: =SUMIF('Week1'!$A:$A,$A16,'Week1'!$K:$K)+SUMIF('Week2'!$A:$A,$A16,'Week2'!$K:$K)+SUMIF('Week3'!$A:$A,$A16,'Week3'!$K:$K)+SUMIF('Week4'!$A:$A,$A16,'Week4'!$K:$K)
A17: HARESH CHAGAN EOLL | B17: A-EL PKNG HIGH_RISK | C17: 1633 | D17: =SUMIF('Week1'!$A:$A,$A17,'Week1'!$D:$D)+SUMIF('Week2'!$A:$A,$A17,'Week2'!$D:$D)+SUMIF('Week3'!$A:$A,$A17,'Week3'!$D:$D)+SUMIF('Week4'!$A:$A,$A17,'Week4'!$D:$D) | E17: =SUMIF('Week1'!$A:$A,$A17,'Week1'!$E:$E)+SUMIF('Week2'!$A:$A,$A17,'Week2'!$E:$E)+SUMIF('Week3'!$A:$A,$A17,'Week3'!$E:$E)+SUMIF('Week4'!$A:$A,$A17,'Week4'!$E:$E) | F17: =SUMIF('Week1'!$A:$A,$A17,'Week1'!$F:$F)+SUMIF('Week2'!$A:$A,$A17,'Week2'!$F:$F)+SUMIF('Week3'!$A:$A,$A17,'Week3'!$F:$F)+SUMIF('Week4'!$A:$A,$A17,'Week4'!$F:$F) | G17: =SUMIF('Week1'!$A:$A,$A17,'Week1'!$G:$G)+SUMIF('Week2'!$A:$A,$A17,'Week2'!$G:$G)+SUMIF('Week3'!$A:$A,$A17,'Week3'!$G:$G)+SUMIF('Week4'!$A:$A,$A17,'Week4'!$G:$G) | H17: =SUMIF('Week1'!$A:$A,$A17,'Week1'!$H:$H)+SUMIF('Week2'!$A:$A,$A17,'Week2'!$H:$H)+SUMIF('Week3'!$A:$A,$A17,'Week3'!$H:$H)+SUMIF('Week4'!$A:$A,$A17,'Week4'!$H:$H) | I17: =SUMIF('Week1'!$A:$A,$A17,'Week1'!$I:$I)+SUMIF('Week2'!$A:$A,$A17,'Week2'!$I:$I)+SUMIF('Week3'!$A:$A,$A17,'Week3'!$I:$I)+SUMIF('Week4'!$A:$A,$A17,'Week4'!$I:$I) | J17: =SUMIF('Week1'!$A:$A,$A17,'Week1'!$J:$J)+SUMIF('Week2'!$A:$A,$A17,'Week2'!$J:$J)+SUMIF('Week3'!$A:$A,$A17,'Week3'!$J:$J)+SUMIF('Week4'!$A:$A,$A17,'Week4'!$J:$J) | K17: =SUMIF('Week1'!$A:$A,$A17,'Week1'!$K:$K)+SUMIF('Week2'!$A:$A,$A17,'Week2'!$K:$K)+SUMIF('Week3'!$A:$A,$A17,'Week3'!$K:$K)+SUMIF('Week4'!$A:$A,$A17,'Week4'!$K:$K)
A18: ANKIT CHOTALA EOLL | B18: A-EL PKNG HIGH_RISK | C18: 1649 | D18: =SUMIF('Week1'!$A:$A,$A18,'Week1'!$D:$D)+SUMIF('Week2'!$A:$A,$A18,'Week2'!$D:$D)+SUMIF('Week3'!$A:$A,$A18,'Week3'!$D:$D)+SUMIF('Week4'!$A:$A,$A18,'Week4'!$D:$D) | E18: =SUMIF('Week1'!$A:$A,$A18,'Week1'!$E:$E)+SUMIF('Week2'!$A:$A,$A18,'Week2'!$E:$E)+SUMIF('Week3'!$A:$A,$A18,'Week3'!$E:$E)+SUMIF('Week4'!$A:$A,$A18,'Week4'!$E:$E) | F18: =SUMIF('Week1'!$A:$A,$A18,'Week1'!$F:$F)+SUMIF('Week2'!$A:$A,$A18,'Week2'!$F:$F)+SUMIF('Week3'!$A:$A,$A18,'Week3'!$F:$F)+SUMIF('Week4'!$A:$A,$A18,'Week4'!$F:$F) | G18: =SUMIF('Week1'!$A:$A,$A18,'Week1'!$G:$G)+SUMIF('Week2'!$A:$A,$A18,'Week2'!$G:$G)+SUMIF('Week3'!$A:$A,$A18,'Week3'!$G:$G)+SUMIF('Week4'!$A:$A,$A18,'Week4'!$G:$G) | H18: =SUMIF('Week1'!$A:$A,$A18,'Week1'!$H:$H)+SUMIF('Week2'!$A:$A,$A18,'Week2'!$H:$H)+SUMIF('Week3'!$A:$A,$A18,'Week3'!$H:$H)+SUMIF('Week4'!$A:$A,$A18,'Week4'!$H:$H) | I18: =SUMIF('Week1'!$A:$A,$A18,'Week1'!$I:$I)+SUMIF('Week2'!$A:$A,$A18,'Week2'!$I:$I)+SUMIF('Week3'!$A:$A,$A18,'Week3'!$I:$I)+SUMIF('Week4'!$A:$A,$A18,'Week4'!$I:$I) | J18: =SUMIF('Week1'!$A:$A,$A18,'Week1'!$J:$J)+SUMIF('Week2'!$A:$A,$A18,'Week2'!$J:$J)+SUMIF('Week3'!$A:$A,$A18,'Week3'!$J:$J)+SUMIF('Week4'!$A:$A,$A18,'Week4'!$J:$J) | K18: =SUMIF('Week1'!$A:$A,$A18,'Week1'!$K:$K)+SUMIF('Week2'!$A:$A,$A18,'Week2'!$K:$K)+SUMIF('Week3'!$A:$A,$A18,'Week3'!$K:$K)+SUMIF('Week4'!$A:$A,$A18,'Week4'!$K:$K)
... A216: BERNARDO FERNANDES RESPONSE | B216: A-RS PROD BELT | C216: 1675 | D216: =SUMIF('Week1'!$A:$A,$A216,'Week1'!$D:$D)+SUMIF('Week2'!$A:$A,$A216,'Week2'!$D:$D)+SUMIF('Week3'!$A:$A,$A216,'Week3'!$D:$D)+SUMIF('Week4'!$A:$A,$A216,'Week4'!$D:$D) | E216: =SUMIF('Week1'!$A:$A,$A216,'Week1'!$E:$E)+SUMIF('Week2'!$A:$A,$A216,'Week2'!$E:$E)+SUMIF('Week3'!$A:$A,$A216,'Week3'!$E:$E)+SUMIF('Week4'!$A:$A,$A216,'Week4'!$E:$E) | F216: =SUMIF('Week1'!$A:$A,$A216,'Week1'!$F:$F)+SUMIF('Week2'!$A:$A,$A216,'Week2'!$F:$F)+SUMIF('Week3'!$A:$A,$A216,'Week3'!$F:$F)+SUMIF('Week4'!$A:$A,$A216,'Week4'!$F:$F) | G216: =SUMIF('Week1'!$A:$A,$A216,'Week1'!$G:$G)+SUMIF('Week2'!$A:$A,$A216,'Week2'!$G:$G)+SUMIF('Week3'!$A:$A,$A216,'Week3'!$G:$G)+SUMIF('Week4'!$A:$A,$A216,'Week4'!$G:$G) | H216: =SUMIF('Week1'!$A:$A,$A216,'Week1'!$H:$H)+SUMIF('Week2'!$A:$A,$A216,'Week2'!$H:$H)+SUMIF('Week3'!$A:$A,$A216,'Week3'!$H:$H)+SUMIF('Week4'!$A:$A,$A216,'Week4'!$H:$H) | I216: =SUMIF('Week1'!$A:$A,$A216,'Week1'!$I:$I)+SUMIF('Week2'!$A:$A,$A216,'Week2'!$I:$I)+SUMIF('Week3'!$A:$A,$A216,'Week3'!$I:$I)+SUMIF('Week4'!$A:$A,$A216,'Week4'!$I:$I) | J216: =SUMIF('Week1'!$A:$A,$A216,'Week1'!$J:$J)+SUMIF('Week2'!$A:$A,$A216,'Week2'!$J:$J)+SUMIF('Week3'!$A:$A,$A216,'Week3'!$J:$J)+SUMIF('Week4'!$A:$A,$A216,'Week4'!$J:$J) | K216: =SUMIF('Week1'!$A:$A,$A216,'Week1'!$K:$K)+SUMIF('Week2'!$A:$A,$A216,'Week2'!$K:$K)+SUMIF('Week3'!$A:$A,$A216,'Week3'!$K:$K)+SUMIF('Week4'!$A:$A,$A216,'Week4'!$K:$K)
A218: Category totals (month)
A219: Sum of hours by work category — calculated with SUMIFS from the employee table above.
B220: Category | D220: Basic hours | E220: Mon–Fri overtime | F220: Sat/Sun overtime | G220: Annual holiday | H220: Total paid hours
B221: A-EL CLNR | D221: =SUMIFS($D$7:$D$216,$B$7:$B$216,$B221) | E221: =SUMIFS($E$7:$E$216,$B$7:$B$216,$B221) | F221: =SUMIFS($F$7:$F$216,$B$7:$B$216,$B221) | G221: =SUMIFS($G$7:$G$216,$B$7:$B$216,$B221) | H221: =SUMIFS($H$7:$H$216,$B$7:$B$216,$B221)
B222: A-EL DPCH | D222: =SUMIFS($D$7:$D$216,$B$7:$B$216,$B222) | E222: =SUMIFS($E$7:$E$216,$B$7:$B$216,$B222) | F222: =SUMIFS($F$7:$F$216,$B$7:$B$216,$B222) | G222: =SUMIFS($G$7:$G$216,$B$7:$B$216,$B222) | H222: =SUMIFS($H$7:$H$216,$B$7:$B$216,$B222)
B223: A-EL OFCE | D223: =SUMIFS($D$7:$D$216,$B$7:$B$216,$B223) | E223: =SUMIFS($E$7:$E$216,$B$7:$B$216,$B223) | F223: =SUMIFS($F$7:$F$216,$B$7:$B$216,$B223) | G223: =SUMIFS($G$7:$G$216,$B$7:$B$216,$B223) | H223: =SUMIFS($H$7:$H$216,$B$7:$B$216,$B223)
B224: A-EL PKNG HIGH_RISK | D224: =SUMIFS($D$7:$D$216,$B$7:$B$216,$B224) | E224: =SUMIFS($E$7:$E$216,$B$7:$B$216,$B224) | F224: =SUMIFS($F$7:$F$216,$B$7:$B$216,$B224) | G224: =SUMIFS($G$7:$G$216,$B$7:$B$216,$B224) | H224: =SUMIFS($H$7:$H$216,$B$7:$B$216,$B224)
B225: A-EL PKNG SLEEVING | D225: =SUMIFS($D$7:$D$216,$B$7:$B$216,$B225) | E225: =SUMIFS($E$7:$E$216,$B$7:$B$216,$B225) | F225: =SUMIFS($F$7:$F$216,$B$7:$B$216,$B225) | G225: =SUMIFS($G$7:$G$216,$B$7:$B$216,$B225) | H225: =SUMIFS($H$7:$H$216,$B$7:$B$216,$B225)
B226: A-EL PROD BELT | D226: =SUMIFS($D$7:$D$216,$B$7:$B$216,$B226) | E226: =SUMIFS($E$7:$E$216,$B$7:$B$216,$B226) | F226: =SUMIFS($F$7:$F$216,$B$7:$B$216,$B226) | G226: =SUMIFS($G$7:$G$216,$B$7:$B$216,$B226) | H226: =SUMIFS($H$7:$H$216,$B$7:$B$216,$B226)
B227: A-EL PROD FORMING | D227: =SUMIFS($D$7:$D$216,$B$7:$B$216,$B227) | E227: =SUMIFS($E$7:$E$216,$B$7:$B$216,$B227) | F227: =SUMIFS($F$7:$F$216,$B$7:$B$216,$B227) | G227: =SUMIFS($G$7:$G$216,$B$7:$B$216,$B227) | H227: =SUMIFS($H$7:$H$216,$B$7:$B$216,$B227)
B228: A-EL PROD FRYING | D228: =SUMIFS($D$7:$D$216,$B$7:$B$216,$B228) | E228: =SUMIFS($E$7:$E$216,$B$7:$B$216,$B228) | F228: =SUMIFS($F$7:$F$216,$B$7:$B$216,$B228) | G228: =SUMIFS($G$7:$G$216,$B$7:$B$216,$B228) | H228: =SUMIFS($H$7:$H$216,$B$7:$B$216,$B228)
B229: A-EL PROD PREPARATION | D229: =SUMIFS($D$7:$D$216,$B$7:$B$216,$B229) | E229: =SUMIFS($E$7:$E$216,$B$7:$B$216,$B229) | F229: =SUMIFS($F$7:$F$216,$B$7:$B$216,$B229) | G229: =SUMIFS($G$7:$G$216,$B$7:$B$216,$B229) | H229: =SUMIFS($H$7:$H$216,$B$7:$B$216,$B229)
B230: A-EL TECHNICAL | D230: =SUMIFS($D$7:$D$216,$B$7:$B$216,$B230) | E230: =SUMIFS($E$7:$E$216,$B$7:$B$216,$B230) | F230: =SUMIFS($F$7:$F$216,$B$7:$B$216,$B230) | G230: =SUMIFS($G$7:$G$216,$B$7:$B$216,$B230) | H230: =SUMIFS($H$7:$H$216,$B$7:$B$216,$B230)
B231: A-EL WRHS | D231: =SUMIFS($D$7:$D$216,$B$7:$B$216,$B231) | E231: =SUMIFS($E$7:$E$216,$B$7:$B$216,$B231) | F231: =SUMIFS($F$7:$F$216,$B$7:$B$216,$B231) | G231: =SUMIFS($G$7:$G$216,$B$7:$B$216,$B231) | H231: =SUMIFS($H$7:$H$216,$B$7:$B$216,$B231)
B232: A-PM PKNG HIGH_RISK | D232: =SUMIFS($D$7:$D$216,$B$7:$B$216,$B232) | E232: =SUMIFS($E$7:$E$216,$B$7:$B$216,$B232) | F232: =SUMIFS($F$7:$F$216,$B$7:$B$216,$B232) | G232: =SUMIFS($G$7:$G$216,$B$7:$B$216,$B232) | H232: =SUMIFS($H$7:$H$216,$B$7:$B$216,$B232)
... B247: WRHS | D247: =SUMIFS($D$7:$D$216,$B$7:$B$216,$B247) | E247: =SUMIFS($E$7:$E$216,$B$7:$B$216,$B247) | F247: =SUMIFS($F$7:$F$216,$B$7:$B$216,$B247) | G247: =SUMIFS($G$7:$G$216,$B$7:$B$216,$B247) | H247: =SUMIFS($H$7:$H$216,$B$7:$B$216,$B247)
A249: Grouped totals (month)
A250: Categories rolled up to 4-character groups across all weeks.
B251: Category | D251: Basic hours | E251: Mon–Fri overtime | F251: Sat/Sun overtime | G251: Annual holiday | H251: Total paid hours
B252: A-EL CLNR | D252: 808.5 | E252: 54 | F252: 9.75 | G252: 0 | H252: 872.25
B253: A-EL DPCH | D253: 70.25 | E253: 6.25 | F253: 0 | G253: 0 | H253: 76.5
B254: A-EL OFCE | D254: 151.25 | E254: 0 | F254: 0 | G254: 0 | H254: 151.25
B255: A-EL PKNG | D255: 2147.25 | E255: 39 | F255: 0 | G255: 0 | H255: 2186.25
...
